Workbook
Name Issue_Type: Table3[Issue Type]
Name Slicer_Impact: #N/A
Name Slicer_Impact1: #N/A
Name Slicer_Issue_owner1: #N/A
Name Slicer_Issue_Type: #N/A
Name Slicer_Name: #N/A
Name Slicer_Name1: #N/A
Name Slicer_Priority_by_Alfanar: #N/A
Name Slicer_Priority_by_SEC: #N/A
Name Slicer_Project: #N/A
Name Slicer_Project1: #N/A
Name Slicer_Region: #N/A
Name Slicer_Status: #N/A

Sheet Sheet3
A1: Supply chain-Purchasing
A2: Resource Department
A3: Treasury

Sheet All Issues
X2: A | Y2: Extremely High
X3: B | Y3: High
X4: C | Y4: Medium
Y5: Low
W8: AES-WESTERN | X8: Alfanar AES Meeting Updated Tracker Status 28th May 25.xlsx
B10: Project | C10: Project Name | D10: Project Manager | E10: Region | F10: SN | G10: Issue owner | H10: Name | I10: Issue Type | J10: Date Issued | K10: Main Issue | L10: Impact | M10: Action Taken | N10: Action Required | O10: Priority By SEC | P10: Priority by Alfanar | Q10: Action By | R10: Planned Target | S10: Forecast/Expected Target | T10: Status | U10: (Schedule/Cost)Impact | V10: Remarks | W10: Cost | X10: PO Status
B11: PE-243 | C11: (DRPC) at Tabuk 380KV BSP | D11: Shafqat Zia | E11: Western | F11: 1 | G11: Alfanar | H11: Supply chain-Purchasing | I11: Delivery | K11: Revised Purchase order for TSC panel to GE from SCD | L11: High | M11: PM following with SCD to issues the p.o, Budget supplement of TSC Panel is under Ex VP approval | N11: SCD need to be issued the P.O to GE, it will affect the FAC issuance | O11: A | P11: A | Q11: PM/SCD/RM | T11: Closed
B12: PE-243 | C12: (DRPC) at Tabuk 380KV BSP | D12: Shafqat Zia | E12: Western | F12: 1 | G12: Alfanar | H12: Supply chain-Purchasing | I12: VO/EOT | K12: SCD need to finalize Alfanar claim to GE (10.2 million SAR) | L12: High | M12: PM following with scd settle the claim, Diemention changes in the tranformer. | N12: SCD need to be settled alfanar claim at earliest | O12: A | P12: A | Q12: PM/SCD/RM | T12: Closed
B13: PE-270 | C13: 110/13.8KV HARAZAT SUB JEDDAH | D13: Muhammed Ilyas | E13: Western | F13: 1 | G13: Client | H13: SEC | I13: Client Issues | K13: Fiber & Data Route Establishment | L13: High | M13: Following with SEC | N13: SEC need to provide | O13: A | P13: A | Q13: PM | T13: Closed | V13: For Energization
B14: PE-270 | C14: 110/13.8KV HARAZAT SUB JEDDAH | D14: Muhammed Ilyas | E14: Western | F14: 1 | G14: Client | H14: SEC | I14: Client Issues | K14: 1. Final Settings of Line Protection Panels. (Testing will be done, once line readiness from client). 2. AMI integration with WRCC | L14: High | M14: Following up with SEC | N14: SEC need to expedite | O14: A | P14: A | Q14: PM | S14: Dependent on Line Readiness from Client | T14: Open | V14: For Energization
B15: PE-265 | C15: 110/33 KV ALMAHANI S/S IN TAIF | D15: Sohaib Afdal | E15: Western | F15: 1 | G15: Vendor | H15: HITACHI | I15: Delivery | K15: Complete Production (11 bays) status for the 110kv GIS and LCC panels, not yet confirmed by Hitachi | L15: High | M15: Email communication and followup with Hitachi team to expeditet the delivery | N15: Hitachi need to confirm the status of Complete produciton status and FAT Date. As per p.o terms delivery by 28th Jan 25. | O15: A | P15: A | Q15: Vendor | R15: 45784 | T15: Closed | X15: "P.O issued on ( Jan 24). (LOA signed on 20-Aug-23, GAFM date by 28th Jan 24) Delivery 13 months from LOA signed date and 10 month from GAFM , as per P.O delivery by . 28-Jan-25. Delivery to be expedited. GIS Material is partially delivered to site. waiting for CT&PT approval
B16: PE-265 | C16: 110/33 KV ALMAHANI S/S IN TAIF | D16: Sohaib Afdal | E16: Western | F16: 2 | G16: Client | H16: SEC | I16: Test & Comm. | K16: delay in final setting approval and Line Parameters for SWGR and Capacitor bank and line protection delaying open loop test | L16: High | M16: Submittal was provided to SEC requesting the approval to proceed Letter submitted to SE highlighting the key issues holding the testing progress | N16: Need to expedite final setting approval for SWGR and Capacitor bank and line protection to proceed immediately with Open Loop Tests | O16: A | P16: A | Q16: PM/SEC | R16: 46233 | S16: 46233 | T16: Open
B17: PE-265 | C17: 110/33 KV ALMAHANI S/S IN TAIF | D17: Sohaib Afdal | E17: Western | F17: 2 | G17: Alfanar | H17: AP / SE | I17: Installation | K17: Delayed installations of the (HV Terminations, CSE, MV Terminations) pending qualified subcontractor. | L17: High | M17: Prequalification Submitted to SE, Awaiting Approval to Close the PO | N17: support with SE to finalize the prequalification to close the PO | O17: A | P17: A | Q17: Vendor | R17: 46233 | S17: 46233 | T17: Open | X17: Material delivered (except for MV Terminations, expected by 1st week of Aug-26)
B18: PE-265 | C18: 110/33 KV ALMAHANI S/S IN TAIF | D18: Sohaib Afdal | E18: Western | F18: 2 | G18: Alfanar | H18: AP / SE | I18: Construction | K18: Costly design of the road works connection with the main road that will require additional 1.6m to the available Asphalt PO | L18: High | M18: Alternative offers were acquired with 0.9M SAR, however still no Budget to proceed with the current design | N18: Arrange with SE to agree on a proposal to link the road, SCD to provide Cheaper offers | O18: A | P18: A | Q18: Vendor | R18: 46233 | S18: 46264 | T18: Open
B19: PE-265 | C19: 110/33 KV ALMAHANI S/S IN TAIF | D19: Sohaib Afdal | E19: Western | F19: 2 | G19: Vendor | H19: HITACHI | I19: Delivery | K19: MV Capacitor Banks, During unpacking of the MV Capacitor Bank units, one unit out of four was found damaged with oil leakage, rendering it defective and unfit for installation. The unit requires full replacement. | L19: High | M19: HITACHI was formally notified of the damaged unit and requested to propose a replacement solution. HITACHI confirmed remanufacturing of a replacement unit, with delivery estimated by Aug-26. | N19: HITACHI to formally assess responsibility for transit damage and explore schedule acceleration options (priority manufacturing, parallel FAT, or air shipment where feasible). | O19: A | P19: A | Q19: Vendor | R19: 46203 | S19: 46264 | T19: Closed | U19: additional 3 months delay | X19: Material delivered
B20: PE-265 | C20: 110/33 KV ALMAHANI S/S IN TAIF | D20: Sohaib Afdal | E20: Western | F20: 3 | G20: Vendor | H20: SPTC | I20: Delivery | K20: Power Transformer 80/100 MVA Delivery | L20: High | M20: Mail shared to supplier,supplier informed FAT from 22nd May to 29th May. | N20: FAT date to be improved by end of Apr. Need delivery by 10th May 25 | O20: A | P20: A | Q20: Vendor/PM | R20: 45767 | S20: 45807 | T20: Closed | U20: Three month impact | X20: P.O issued on 4th Sep 24, Delivery period 16.5 Months from p.o issuancw. as per P.O delivery by 21th Jan 25, delivery to be expedited.Delivery is expected on 15-Jul-25 FAT Is completed.
B21: PE-265 | C21: 110/33 KV ALMAHANI S/S IN TAIF | D21: Sohaib Afdal | E21: Western | F21: 4 | G21: Vendor | H21: Prainsa | I21: Installation | K21: 110KV Building precast material delivery and instllation delayed, till date no materials delivered at site | L21: High | M21: Supplier send the plan for delivery by Mid of may and installation by mid of June, Alfanar not accepted. | N21: Supplier should supply all the materials immediately and installation need to complete by end of May-25 | O21: A | P21: A | Q21: Vendor/PM | R21: 45762 | S21: 45792 | T21: Closed | U21: One month impact | X21: All precast material is delivered
B22: PE-265 | C22: 110/33 KV ALMAHANI S/S IN TAIF | D22: Sohaib Afdal | E22: Western | F22: 5 | G22: Client | H22: SEC | I22: Delivery | K22: 110kv GIS ct-vt-Exceptional approval | L22: high | M22: Email communication and followup | N22: sec NEED TO APPROVE THE EXCEPTIONAL APPROVAL | O22: A | P22: A | Q22: Client/PM | T22: Closed | X22: Still SEC not replied.
B23: PE-265 | C23: 110/33 KV ALMAHANI S/S IN TAIF | D23: Sohaib Afdal | E23: Western | F23: 6 | G23: Vendor | H23: DAR | I23: Design Submission / Rectifications | K23: Delay in Submission and revision comments reply by DAR | L23: High | M23: E-mails and follow up is made with DAR Team to submit design pending works | N23: Dar need to Expedite the compliance SEC comments and submit revisions within 3-4 days | O23: A | P23: A | Q23: Vendor | T23: Closed | V23: Al Mahani Dar submittal tracking (22-Apr-25).xlsx | X23: Now DAR is replying for Comments from SEC
B24: PE-315 | C24: 110KV Salam Royal Palace | D24: Ahmed Faisal | E24: Western | F24: 1 | G24: Vendor | H24: M/S FAWAZ REFR & AIRCONDITIONING | I24: Delivery | K24: Ventilation Fans & Smoke Purging Fans-Delivery | L24: Extremely High | M24: Vendor has confirmed the shipment will start by 15th Aug 25 and expected delivery will be 30th Sep’2 which affect the TCC date. | N24: Expedite the vendor to start the shipment immediately. | O24: A | P24: A | Q24: Vendor/PM | S24: 45930 | T24: Closed | U24: One month impact
B25: PE-315 | C25: 110KV Salam Royal Palace | D25: Ahmed Faisal | E25: Western | F25: 2 | G25: Vendor | H25: AES | I25: Delivery | K25: Protection Panel-Consumer feeder is still pending and expected delivery 10th july'25.FAT for 5 panels completed on yesterday | L25: Medium | M25: Continous follow up and meeting to expedite the delivery. | N25: AES should deliver the consumer feeder by 10th July'25 as committed. | O25: C | P25: C | Q25: Vendor/PM | R25: 45777 | S25: 45848 | T25: Closed | U25: No impact
B26: PE-315 | C26: 110KV Salam Royal Palace | D26: Ahmed Faisal | E26: Western | F26: 3 | G26: Vendor | H26: AES | I26: Delivery | K26: ACDC Lighting Panel-FAT date yet to be confirmed. Base design approved on 8th May'25.We are pushing AES to the target FAT date of 15th July'25. | L26: High | M26: Continous follow up and meeting to expedite the delivery. | N26: Expedite the AES to the target FAT date of 15th July'25 | O26: B | P26: B | Q26: Vendor/PM | R26: 45777 | S26: 45853 | T26: Closed | U26: No impact
B27: PE-315 | C27: 110KV Salam Royal Palace | D27: Ahmed Faisal | E27: Western | F27: 4 | G27: Vendor | H27: AES | I27: Delivery | K27: Station Service Transformer-FAT will be on 30th Aug'25.Expected delivery by Sep'25 | L27: Extremely High | M27: Continous follow up and meeting to expedite the delivery. | N27: AES should improve the FAT date before 15th July'25. | O27: A | P27: A | Q27: Vendor/PM | R27: 45762 | S27: 45792 | T27: Closed | U27: 2 months impact
B28: PE-315 | C28: 110KV Salam Royal Palace | D28: Ahmed Faisal | E28: Western | F28: 5 | G28: Vendor | H28: LEEEC | I28: Delivery | K28: Power Transformer-RFS issued. However , shipment still not processed waiting conclusion of SEC visit to M/S LEEEC factory. | L28: Extremely High | M28: FAT completed on 10 Mar'25.Due to quality inspection,SEC visited the factory and review the comments give release for shipment. | N28: LEEEC should deliver the power transformer by 1st Aug'25. | O28: A | P28: A | Q28: Vendor/PM | R28: 45839 | S28: 45901 | T28: Closed | U28: 2 months impact
B29: PE-315 | C29: 110KV Salam Royal Palace | D29: Ahmed Faisal | E29: Western | F29: 6 | G29: Client | H29: SEC/Royal Palace Security team | I29: Delivery | K29: Security system & Access control scope yet to be finalized by SEC & Royal Palace security team. | L29: Extremely High | M29: PO finalized to Etech and awaiting for Technical Submittal. | N29: SEC should confirm the security system scope required or not for this project. | O29: A | P29: A | Q29: SEC/PM | S29: 45853 | T29: Closed
B30: PE-315 | C30: 110KV Salam Royal Palace | D30: Ahmed Faisal | E30: Western | F30: 7 | G30: Client | H30: SEC | I30: Delivery | K30: Cable route finalized 25th june'25 and given for manufacturing clearance.Submitted schematic diagram to SEC. | L30: Extremely High | M30: Submitted the schematic diagram to SEC.Once we get approval,we will start civil works. | N30: SEC should expedite the approval of cable route outside palace. | O30: A | P30: A | Q30: SEC/PM | S30: 45845 | T30: Closed | U30: 2 months impact
B31: PE-280 | C31: 110KV SS - KAEC-2 | D31: Hossam Mahrous | E31: Western | F31: 1 | G31: Client | H31: SEC | I31: Permits / Request from Client | K31: Armored cable requirement for LV cable | L31: Extremely High | M31: Matter has been highlighted to SEC & EMAAR as well | N31: Armored Cable requirement to be waived off from SEC & Issue highlighted to SEC & KAEC as well. PM to have close follow-up with SEC/KAEC to resolve the issue | O31: B | P31: B | Q31: Client/PM | R31: 45777 | S31: 45777 | T31: Closed | U31: One month impact (Cost Impact after vendor quote its price) | V31: Matter has been closed & SEC has approved LV cable design without armor rerquirement | W31: No Impact | X31: PO Placed
B32: PE-280 | C32: 110KV SS - KAEC-2 | D32: Hossam Mahrous | E32: Western | F32: 2 | G32: Client | H32: SEC | I32: Permits / Request from Client | K32: FAT Approval & Delivery for Power Transformer | L32: Extremely High | M32: Letter sent to SEC by VP for two times to expedite FAT & Rectification approval RFSC already given to supplier (Material is stuck with Supplier) | N32: SEC to provide FAT & Rectification approval | O32: B | P32: B | Q32: Client/Vendor/PM | R32: 45802 | S32: 45838 | T32: Closed | U32: One month impact | V32: Power Transformer to be dispatched within this week | W32: No Impact | X32: PO Placed
B33: PE-280 | C33: 110KV SS - KAEC-2 | D33: Hossam Mahrous | E33: Western | F33: 3 | G33: Alfanar | H33: T&C | I33: Resources | K33: Mobilization of T&C team | L33: High | M33: Portfolio Manager has communicated AT&C to finalization of PO | N33: Need support from management in mobilization of T&C team by 1st June 2025 | O33: B | P33: B | Q33: Vendor/PM | R33: 45809 | S33: 45838 | T33: Closed | U33: No Impact | V33: T&C Team starts working at site | W33: No Impact | X33: Under Negotiation
B34: PE-280 | C34: 110KV SS - KAEC-2 | D34: Hossam Mahrous | E34: Western | F34: 4 | G34: Vendor | H34: AES | I34: Delivery | K34: AES to get exceptional approval for (Duplex painting system-Double coat) Service station transformer from SEC. | L34: High | M34: AES has submitted exceptional letter to SEC | N34: AES to get the exceptional approval and delivery to be expedited before 30-Apr-25 | O34: B | P34: B | Q34: Client/Vendor/PM | R34: 45777 | T34: Closed | U34: One month impact | V34: Design approved | W34: No Impact | X34: PO Placed
B35: PE-280 | C35: 110KV SS - KAEC-2 | D35: Hossam Mahrous | E35: Western | F35: 5 | G35: Client | H35: SEC | I35: Permits / Request from Client | K35: Need exceptional approval of Faradol 810 used for capacitor bank | L35: High | M35: Letter sent to SEC by PM GAFM already given to supplier (Material under Manufacturing) | N35: Project team to have close follow-up with SEC to close the matter | O35: B | P35: B | Q35: Client/Vendor/PM | R35: 45855 | S35: 45855 | T35: Closed | U35: No Impact | V35: FAT scheduled on first week of August | W35: No Impact | X35: PO Placed
B36: PE-280 | C36: 110KV SS - KAEC-2 | D36: Hossam Mahrous | E36: Western | F36: 6 | G36: Client | H36: SEC | I36: Permits / Request from Client | K36: Need exceptional approval for battery type HOPPECKE | L36: High | M36: Letter sent to SEC on 23.01.2025 by PM GAFM already given to supplier (Material under Manufacturing) | N36: Project team to have close follow-up with SEC to close the matter | O36: B | P36: B | Q36: Client/Vendor/PM | R36: 45788 | S36: 45838 | T36: Closed | U36: One month impact | V36: FAT completed | W36: No Impact | X36: PO Placed
B37: PE-281 | C37: 110KV SS - KAEC-3 | D37: Hossam Mahrous | E37: Western | F37: 1 | G37: Client | H37: SEC | I37: Permits / Request from Client | K37: Armored cable requirement for LV cable | L37: Extremely High | M37: Matter has been highlighted to SEC & EMAAR as well | N37: Armored Cable requirement to be waived off from SEC & Issue highlighted to SEC & KAEC as well. PM to have close follow-up with SEC/KAEC to resolve the issue | O37: B | P37: B | Q37: Client/PM | R37: 45777 | S37: 45777 | T37: Closed | U37: One month impact (Cost Impact after vendor quote its price) | V37: Matter has been closed & SEC has approved LV cable design without armor rerquirement | W37: No Impact | X37: PO Placed
B38: PE-281 | C38: 110KV SS - KAEC-3 | D38: Hossam Mahrous | E38: Western | F38: 2 | G38: Client | H38: SEC | I38: Permits / Request from Client | K38: FAT Approval & Delivery for Power Transformer | L38: Extremely High | M38: Letter sent to SEC by VP for two times to expedite FAT & Rectification approval RFSC already given to supplier (Material is stuck with Supplier) | N38: SEC to provide FAT & Rectification approval | O38: B | P38: B | Q38: Client/Vendor/PM | R38: 45802 | S38: 45838 | T38: Closed | U38: One month impact | V38: Power Transformer to be dispatched within this week | W38: No Impact | X38: PO Placed
B39: PE-281 | C39: 110KV SS - KAEC-3 | D39: Hossam Mahrous | E39: Western | F39: 3 | G39: Alfanar | H39: T&C | I39: Resources | K39: Mobilization of T&C team | L39: High | M39: Portfolio Manager has communicated AT&C to finalization of PO | N39: Need support from management in mobilization of T&C team by 1st June 2025 | O39: B | P39: B | Q39: Vendor/PM | R39: 45809 | S39: 45838 | T39: Closed | U39: No Impact | V39: T&C Team starts working at site | W39: No Impact | X39: Under Negotiation
B40: PE-281 | C40: 110KV SS - KAEC-3 | D40: Hossam Mahrous | E40: Western | F40: 4 | G40: Vendor | H40: AES | I40: Delivery | K40: AES to get exceptional approval for (Duplex painting system-Double coat) Service station transformer from SEC. | L40: High | M40: AES has submitted exceptional letter to SEC | N40: AES to get the exceptional approval and delivery to be expedited before 30-Apr-25 | O40: B | P40: B | Q40: Client/Vendor/PM | R40: 45777 | T40: Closed | U40: One month impact | V40: Design approved | W40: No Impact | X40: PO Placed
B41: PE-281 | C41: 110KV SS - KAEC-3 | D41: Hossam Mahrous | E41: Western | F41: 5 | G41: Client | H41: SEC | I41: Permits / Request from Client | K41: Need exceptional approval of Faradol 810 used for capacitor bank | L41: High | M41: Letter sent to SEC & under approval | N41: Project team to have close follow-up with SEC to close the matter | O41: B | P41: B | Q41: Client/Vendor/PM | R41: 45855 | S41: 45855 | T41: Closed | U41: No Impact | V41: FAT scheduled on first week of August | W41: No Impact | X41: PO Placed
B42: PE-281 | C42: 110KV SS - KAEC-3 | D42: Hossam Mahrous | E42: Western | F42: 6 | G42: Client | H42: SEC | I42: Permits / Request from Client | K42: Need exceptional approval for battery type HOPPECKE | L42: High | M42: Letter sent to SEC & under approval for battery type | N42: Project team to have close follow-up with SEC to close the matter | O42: B | P42: B | Q42: Client/Vendor/PM | R42: 45788 | S42: 45838 | T42: Closed | U42: One month impact | V42: FAT completed | W42: No Impact | X42: PO Placed
B43: PE-330 | C43: Construction of OTOUD SS and interconnections | D43: Ahmed Hussein | E43: Southern | F43: 1 | G43: Client | H43: SEC | I43: Permits / Request from Client | K43: *Delay of issuing Municipalty permit for Substation due to missing title deed | L43: Medium | M43: Issue is discussed with SEC by Portfolio Manager and PM and Letter is submitted to SEC | N43: SEC to follow Up to get the title deed of the Land | O43: A | P43: A | Q43: SEC | T43: Closed
B44: PE-330 | C44: Construction of OTOUD SS and interconnections | D44: Ahmed Hussein | E44: Southern | F44: 2 | G44: Alfanar | H44: Project Team | I44: Delivery | K44: GIS Manufacturing Duration is very high relative to the 18 Months TCC which is expected to impact the TCC by 6 months delay | L44: High | M44: communicated with the supplier and the manufacturing duration is reduced to 11.5 months (Expected delivery date as stated by Hitachi is 6-Aug-2026 instead of 15-Sep-2026) | N44: Try to make the delivery date earlier to have enough time for Installation & T&C | O44: A | P44: A | Q44: PM | S44: 46301 | T44: Closed | U44: 2 months impact
...

Sheet Statistics
A3: Total No. of issues | B3: =COUNTA(Table1[Project]) -> 508
I4: Issues Log Statistics
A12: Client | B12: =COUNTIFS(Table1[Issue owner],A12,Table1[Status],"open") -> 83
A13: Client/EOT/VO | B13: =COUNTIFS(Table1[Issue owner],A13,Table1[Status],"open") -> 1
A14: Vendor | B14: =COUNTIFS(Table1[Issue owner],A14,Table1[Status],"open") -> 87
A15: Alfanar | B15: =COUNTIFS(Table1[Issue owner],A15,Table1[Status],"open") -> 50
B16: =SUM(B12:B15) -> 221
A17: Vendor | B17: No
A18: SPTC | B18: =COUNTIFS(Table1[Name],Statistics!A18,Table1[Status],"open") -> 2
A19: RITZ | B19: =COUNTIFS(Table1[Name],Statistics!A19,Table1[Status],"open") -> 0
A20: SIEMENS | B20: =COUNTIFS(Table1[Name],Statistics!A20,Table1[Status],"open") -> 2
A21: AES | B21: =COUNTIFS(Table1[Name],Statistics!A21,Table1[Status],"open") -> 17
A22: HITACHI | B22: =COUNTIFS(Table1[Name],Statistics!A22,Table1[Status],"open") -> 21
A23: BCG | B23: =COUNTIFS(Table1[Name],Statistics!A23,Table1[Status],"open") -> 1
A24: LAPP | B24: =COUNTIFS(Table1[Name],Statistics!A24,Table1[Status],"open") -> 1 | J24: Status | K24: Issues No. | L24: % | N24: Criticality | O24: No. | P24: % | R24: Issue Owner | S24: No. | T24: %
A25: Ranco & Zamil | B25: =COUNTIFS(Table1[Name],Statistics!A25,Table1[Status],"open") -> 2 | J25: Open | K25: =B87 -> 222 | L25: =K25/$K$27 -> 0.43960396 | N25: Extremely High | O25: =COUNTIFS(Table1[Impact],Statistics!N25,Table1[Status],"open") -> 97 | P25: =O25/$O$29 -> 0.43693694 | R25: Client | S25: =B12+B13 -> 84 | T25: =S25/$S$28 -> 0.3800905
A26: Arteche | B26: =COUNTIFS(Table1[Name],Statistics!A26,Table1[Status],"open") -> 1 | J26: Closed | K26: =B88 -> 283 | L26: =K26/$K$27 -> 0.56039604 | N26: High | O26: =COUNTIFS(Table1[Impact],Statistics!N26,Table1[Status],"open") -> 102 | P26: =O26/$O$29 -> 0.45945946 | R26: Alfanar | S26: =B15 -> 50 | T26: =S26/$S$28 -> 0.22624434
A27: EPC | B27: =COUNTIFS(Table1[Name],Statistics!A27,Table1[Status],"open") -> 0 | J27: Total No. of issues | K27: =SUM(K25:K26) -> 505 | L27: =K27/$K$27 -> 1 | N27: Medium | O27: =COUNTIFS(Table1[Impact],Statistics!N27,Table1[Status],"open") -> 23 | P27: =O27/$O$29 -> 0.1036036 | R27: Vendor | S27: =B14 -> 87 | T27: =S27/$S$28 -> 0.39366516
A28: DAR | B28: =COUNTIFS(Table1[Name],Statistics!A28,Table1[Status],"open") -> 2 | N28: Low | O28: =COUNTIFS(Table1[Impact],Statistics!N28,Table1[Status],"open") -> 0 | P28: =O28/$O$29 -> 0 | R28: Total No. of issues | S28: =SUM(S25:S27) -> 221 | T28: =S28/$S$28 -> 1
A29: Pfisterer Switzerland AG | B29: =COUNTIFS(Table1[Name],Statistics!A29,Table1[Status],"open") -> 1 | N29: Total No. of issues | O29: =SUM(O25:O28) -> 222 | P29: =O29/$O$29 -> 1
A30: MEFC | B30: =COUNTIFS(Table1[Name],Statistics!A30,Table1[Status],"open") -> 1
A31: NCC | B31: =COUNTIFS(Table1[Name],Statistics!A31,Table1[Status],"open") -> 1
A32: AL WABEL | B32: =COUNTIFS(Table1[Name],Statistics!A32,Table1[Status],"open") -> 1
A33: E-Techs | B33: =COUNTIFS(Table1[Name],Statistics!A33,Table1[Status],"open") -> 0
A34: Tridelta | B34: =COUNTIFS(Table1[Name],Statistics!A34,Table1[Status],"open") -> 0
A35: MSCL | B35: =COUNTIFS(Table1[Name],Statistics!A35,Table1[Status],"open") -> 0
A36: Al Majal | B36: =COUNTIFS(Table1[Name],Statistics!A36,Table1[Status],"open") -> 0
A37: Hyosung | B37: =COUNTIFS(Table1[Name],Statistics!A37,Table1[Status],"open") -> 1
A38: Hyundai | B38: =COUNTIFS(Table1[Name],Statistics!A38,Table1[Status],"open") -> 1
A39: ABB | B39: =COUNTIFS(Table1[Name],Statistics!A39,Table1[Status],"open") -> 1
A40: M/S FAWAZ REFR & AIRCONDITIONING | B40: =COUNTIFS(Table1[Name],Statistics!A40,Table1[Status],"open") -> 0
A41: Prainsa | B41: =COUNTIFS(Table1[Name],Statistics!A41,Table1[Status],"open") -> 0
... A60: Applus | B60: =COUNTIFS(Table1[Name],Statistics!A60,Table1[Status],"open") -> 0
B65: =SUM(B18:B64) -> 80
A74: Alfanar Dep. | B74: Issues No.
A75: Supply chain-Purchasing | B75: =COUNTIFS(Table1[Name],Statistics!A75,Table1[Status],"open") -> 6
A76: Resource Department | B76: =COUNTIFS(Table1[Name],Statistics!A76,Table1[Status],"open") -> 1
A77: PMO | B77: =COUNTIFS(Table1[Name],Statistics!A77,Table1[Status],"open") -> 0
A78: BUSINESS OPERATIONS SUPPORT | B78: =COUNTIFS(Table1[Name],Statistics!A78,Table1[Status],"open") -> 0
A79: Treasury | B79: =COUNTIFS(Table1[Name],Statistics!A79,Table1[Status],"open") -> 0
...

Sheet Sheet1
B2: SPTC
B3: RITZ
B4: SIEMENS
B5: AES
B6: HITACHI
B7: BCG
B8: LAPP
B9: Hitachi
B10: Arteche
B11: EPC
B12: DAR
B13: Pfisterer Switzerland AG
... B28: Moneer Al Boqami

Sheet May 25 - Achievement
A1: Achievement

Sheet Urgent Support List

Sheet Lists
A1: Status | D1: Issue Type | E1: No. Issues | G1: Issue Owner
A2: Open | D2: Design inputs | E2: =COUNTIFS(Table1[Issue Type],Table3[[#This Row],[Issue Type]],Table1[Status],"open") -> 11 | G2: Client
A3: Closed | D3: Delivery | E3: =COUNTIFS(Table1[Issue Type],Table3[[#This Row],[Issue Type]],Table1[Status],"open") -> 58 | G3: Client/EOT/VO | Q3: HITACHI
D4: Installation | E4: =COUNTIFS(Table1[Issue Type],Table3[[#This Row],[Issue Type]],Table1[Status],"open") -> 11 | G4: Vendor | Q4: SPTC
D5: Test & Comm. | E5: =COUNTIFS(Table1[Issue Type],Table3[[#This Row],[Issue Type]],Table1[Status],"open") -> 6 | G5: Client | Q5: SIEMENS
D6: Design Submission / Rectifications | E6: =COUNTIFS(Table1[Issue Type],Table3[[#This Row],[Issue Type]],Table1[Status],"open") -> 27 | G6: Alfanar | K6: Vendors | L6: Design inputs | Q6: RITZ
D7: Resources | E7: =COUNTIFS(Table1[Issue Type],Table3[[#This Row],[Issue Type]],Table1[Status],"open") -> 2 | K7: Vendors | L7: Delivery | Q7: TRENCH
D8: PO Issuance Delay | E8: =COUNTIFS(Table1[Issue Type],Table3[[#This Row],[Issue Type]],Table1[Status],"open") -> 8 | K8: Vendors | L8: Installation | Q8: AES
D9: Revised PO | E9: =COUNTIFS(Table1[Issue Type],Table3[[#This Row],[Issue Type]],Table1[Status],"open") -> 0 | K9: Vendors | L9: Test & Comm. | Q9: BCG
D10: Local Content | E10: =COUNTIFS(Table1[Issue Type],Table3[[#This Row],[Issue Type]],Table1[Status],"open") -> 0 | K10: Vendors | L10: Design Submission / Rectifications | Q10: LAPP
D11: IQAMA Issues | E11: =COUNTIFS(Table1[Issue Type],Table3[[#This Row],[Issue Type]],Table1[Status],"open") -> 0 | K11: Resources | L11: Resources | Q11: Hitachi
D12: Construction | E12: =COUNTIFS(Table1[Issue Type],Table3[[#This Row],[Issue Type]],Table1[Status],"open") -> 24 | K12: Procurement | L12: PO Issuance Delay | Q12: Arteche
D13: Treasury | E13: =COUNTIFS(Table1[Issue Type],Table3[[#This Row],[Issue Type]],Table1[Status],"open") -> 0 | K13: Procurement | L13: Revised PO | Q13: EPC
D14: Permits / Request from Client | E14: =COUNTIFS(Table1[Issue Type],Table3[[#This Row],[Issue Type]],Table1[Status],"open") -> 15 | L14: Local Content | Q14: DAR
D15: Shutdown | E15: =COUNTIFS(Table1[Issue Type],Table3[[#This Row],[Issue Type]],Table1[Status],"open") -> 9 | L15: IQAMA Issues | Q15: NCC
D16: VO/EOT | E16: =COUNTIFS(Table1[Issue Type],Table3[[#This Row],[Issue Type]],Table1[Status],"open") -> 5 | L16: Construction | Q16: LEEEC
D17: Client Issues | E17: =COUNTIFS(Table1[Issue Type],Table3[[#This Row],[Issue Type]],Table1[Status],"open") -> 18 | Q17: AL WABEL
D18: Tender | E18: =COUNTIFS(Table1[Issue Type],Table3[[#This Row],[Issue Type]],Table1[Status],"open") -> 0 | Q18: E-Techs
D19: Close Out | E19: =COUNTIFS(Table1[Issue Type],Table3[[#This Row],[Issue Type]],Table1[Status],"open") -> 2 | Q19: Tri Delta
D20: Funding | E20: =COUNTIFS(Table1[Issue Type],Table3[[#This Row],[Issue Type]],Table1[Status],"open") -> 2 | Q20: MSCL
D21: FAT Test | E21: =COUNTIFS(Table1[Issue Type],Table3[[#This Row],[Issue Type]],Table1[Status],"open") -> 0 | Q21: Al Majal
Q22: Hyosung
Q23: Hyundai
Q24: ABB
Q25: Maricon_UAE
Q26: M/S FAWAZ REFR & AIRCONDITIONING
Q27: Prainsa
Q28: Al Babtain
Q29: Moneer Al Boqami
Q30: GE
Q31: Rezayat trading Company

Sheet Vendor Issues
A9: Project | B9: SN | C9: Issue owner | D9: Name | E9: date Issued | F9: Main Issue | G9: Impact | H9: Action Taken | I9: Action Required | J9: Action By | K9: Planned Target | L9: Forecast/Expected Target | M9: Status | N9: (Schedule/Cost)Impact | O9: Remarks
A10: PE-234 | B10: 3 | C10: Vendor | D10: Hitachi/SEC | E10: 45581 | F10: HV test not yet started which scheduled on 16 Feb 2025. | G10: High | H10: Email sent to the client on 16 Oct 2024 to coordinate with client and supplier to start HV test. On 09 Feb 25 replied by cancelation of HV test and rescheduled by Apr’25 | I10: Client and supplier must expedite in start HV test. | J10: Hitachi/SEC | K10: 45704 | L10: 45762 | M10: Open | N10: Schedule 2 Months
A11: PE-283 | B11: 1 | C11: Vendor | D11: SPTC | E11: 45580 | F11: Delay in manufacturing of Power Transformer by SPTC as the expected FAT is (Aug-25) | G11: High | H11: EOT submitted to recover the delay in Transformer delivery, and it is under approval with SEC | I11: Full support is required from vendor to expedite the material delivery, We should follow up with SEC for the approval of EOT | J11: PM Vendor | K11: 45655 | L11: 45901 | M11: Open | N11: 8 Months Delay | O11: Issue still affecting our project's progress
A12: PE-283 | B12: 2 | C12: Vendor | D12: SIEMENS | E12: 45580 | F12: Delay in manufacturing of SWGR due to design change (Jul-25) | G12: High | H12: Regular meetings and factory visits with SIEMENS are being conducted to expedite the delivery timeline. | I12: Full support is required from vendor to expedite the material delivery. There is a possibility of delivering it by April 2025 if Alfanar covers the transportation cost via air freight (SAR 600K) from Germany to the Jeddah factory. However, this would require senior management approval. | J12: MNGT/PM /Vendor | K12: 45636 | L12: 45839 | M12: Open | N12: 3 Months Delay | O12: Issue still affecting our project's progress
A13: PE-283 | B13: 3 | C13: Vendor | D13: HITACHI | E13: 45580 | F13: Delay in manufacturing of GIS by HITACHI due to manufacturing demand & design change for 2 times | G13: High | H13: Frequent meeting & Factory visit with HITACHI to enhanced LCC Panels delivery to mid of Mar 25, GIS FAT Date , Apr 25 . | I13: Full support is required from vendor to expedite the material delivery. | J13: PM Vendor | K13: 45651 | L13: 45778 | M13: Open | N13: 4 Months Delay | O13: Issue still affecting our project's progress
A14: PE-283 | B14: 4 | C14: Vendor | D14: RITZ | F14: Ther's a delay from the Vendor in supplying (SIS) | G14: High | H14: We make several meetings with them, and also inform Purchase department GAFM has been issued in Aug-24 | I14: Management should take action with them, Letter should be issued to claim their delay from Purchase department | J14: PD/Mng | K14: 45731 | L14: 45838 | M14: Open | N14: 4 Months Delay
A15: PE-283 | B15: 5 | C15: Vendor | D15: TRENCH | E15: 45597 | F15: Delay in manufacturing of out doors CT by TRENCH due to force majeure (Flood) stopped production line at the supplier Factory. | G15: Medium | H15: Frequent meeting with TRENCH to enhance deliver to Apr 25 to mitigate the delay. | I15: Full support is required from vendor to expedite the material delivery. | J15: PM Vendor | K15: 45597 | L15: 45823 | M15: Open | N15: 3 Months Delay
A16: PE-284 | B16: 1 | C16: Vendor | D16: SPTC | E16: 45543 | F16: Delay in manufacturing of Power Transformer by SPTC as the FAT is Aug-25 | G16: High | H16: Frequent meeting & Factory visit with SPTC to enhance deliver before Apr 25 to mitigate the delay as our TCC Contractual is 12-Jul-25​ | I16: Full support is required from vendor to expedite the material delivery, We should follow up with SEC for the approval of EOT | J16: PM/Vendor/Client | K16: 45736 | L16: 45884 | M16: Open | N16: 6 months. | O16: Major delay of project
A17: PE-284 | B17: 3 | C17: Vendor | D17: Hitachi | E17: 45653 | F17: Delay in manufacturing of GIS by HITACHI due to manufacturing demand & design change for 2 times the final date should be confirmed by them | G17: High | H17: Frequent meeting & Factory visit with HITACHI to enhance deliver before Apr25 to mitigate the delay​ | I17: Higher management should take this matter with Hitachi | J17: PM/Vendor/Client | K17: 45725 | L17: 45777 | M17: Open | N17: 2 months
A18: PE-284 | B18: 4 | C18: Vendor | D18: RITZ | E18: 45641 | F18: Ther's a delay from the Vendor in supplying (SIS) | G18: High | H18: We make several meetings with them, and also inform Purchase department GAFM has been issued in Aug-24 | I18: Management should take action with them, Letter should be issued to claim their delay from Purchase department | J18: PD/Mng | K18: 45731 | L18: 45838 | M18: Open | N18: 4 Months Delay
A19: PE-284 | B19: 5 | C19: Vendor | D19: Siemens | E19: 45571 | F19: Delay in manufacturing of SWGR due to design change as the delivery is expected by End of May 25 | G19: Medium | H19: Frequent meeting & Factory visit with SIEMENS to enhance deliver before End of Apr 25 to mitigate the delay​ | I19: Full support is required from vendor to expedite the material delivery. There is a possibility of delivering it by April 2025 if Alfanar covers the transportation cost via air freight (SAR 600K) from Germany to the Jeddah factory. However, this would require senior management approval. | J19: PM/Vendor/Client | K19: 45735 | L19: 45839 | M19: Open | N19: 3 months
A20: PE-284 | B20: 6 | C20: Vendor | D20: Trench | E20: 45623 | F20: Delay in manufacturing of CT by TRENCH due to recent Flood as the expected delivery is May-25 | G20: Medium | H20: Frequent meeting with TRENCH to enhance deliver before MAR25 to mitigate the delay​ | I20: Higher management had made meeting and decided already with TRENCH to deliver in May. ​ | J20: PM/Vendor/Client | K20: 45687 | L20: 45823 | M20: Open | N20: 4 months
A21: PE-298 | B21: 4 | C21: Vendor | D21: AES | E21: 45659 | F21: Delayed GAFM in Protection , Metering and SAS due to delayed Detail Design approval | G21: High | H21: 1. Partial GAFM released for Protection panels 2. Meetings and foolow ups getting conducted for expediting design approvals 3. Close follow up with Factory to get the submittals and compliances | I21: 1.After GAFM required commitment from Alfanar factory for FAT date in line with Project schedule. | J21: PM/Procurement/ vendor | K21: 45667 | L21: 45757 | M21: Open | N21: 70 Days delays | O21: Except SAS panels, GAFM to be released
A22: PE-298 | B22: 5 | C22: Vendor | D22: AES | F22: No Confirmed date from AES for the FAT and Delivery date for Equipment (SWGR, SAS, Protection, Telecom, Panels, Cyper Security) | G22: High | H22: Several Meetings arranged with AES to expedite design phases and Provide GAFM and now waiting for target dates for these Equipment | I22: High management follow up to get the delivery in line with the time schedule | J22: PM | K22: 45867 | L22: 45867 | M22: Open
A23: PE-298 | B23: 6 | C23: Vendor | D23: Hitachi | F23: CBK fuel liquid changed by supplier with anthor liquid oil and it is required to get approval from Sec for the new liquid oil | G23: Medium | H23: Follow up with supplier to confrim that new oil get approval | I23: High supervision with the supplier | J23: PM | K23: 45839 | L23: 45899 | M23: Open
A24: PE-311 | B24: 1 | C24: Vendor | D24: AES | E24: 45656 | F24: Delay from Alfanar factory in providing the designs and delivery date. Such as (Grounding conductor, protection, SAS & telecom, SWGR, Cyper security, Panels).​ | G24: High | H24: Arranged several meetings with AES and a warning letter has been issued. Telecom and Grounding situation has been enhanced. | I24: Close follow up on the remaining Points below: 1. Protection detail design and delivery 2. SAS sysetm Design and Delivery 3. Fault Locator Detail Design and Delivery 4. AES : to share AC Panels base design R02 5. AES : to share DC Panels base design R01 | J24: PM/Vendor/Client | K24: 45921 | L24: 45960 | M24: Open | N24: Schedule. 1 month
A25: PE-311 | B25: 7 | C25: Vendor | D25: LAPP | E25: 45615 | F25: Insulators FAT schedule need to be enhanced from Dec’25 to Oct’2025.​ | G25: Medium | H25: 1. We have issued a letter to SEPDC with force major case due to the fire occurred at Lapp factory 2. Several meeting have been arranged with LAPP to reduce the delivery 3. Lapp confirmed the FAT by October 2025. | I25: Follow up and try to enhnace the delivery more if possible Delivery to be confirmed after GAFM after Plan & Profile approval. | J25: PM/Vendor | K25: 46014 | L25: 46014 | M25: Open | N25: Schedule. 3 month
A26: PE-313 | B26: 2 | C26: Vendor | D26: Hitachi | F26: Delay in receiving the final date of Delivery from Hitachi for 132 KV GIS | G26: High | H26: Several Meetings and mails have been sent from Project team to accelerate the feedback from Vendor | I26: Follow up with the vendor to have final feedback | J26: PM | K26: 45801 | L26: 45823 | M26: Open
A27: PE-313 | B27: 3 | C27: Vendor | D27: SPTC | E27: 45421 | F27: Delay in delivery of 132KV Power Transformer according to vendor’s plan ( SPTC). Delivery in Feb’26.​ | G27: High | H27: Letter has been sent to the client on 09 May' 2024 for swapping the supplier from SPTC to LEEEC to meet the delivery schedule as per planned delivery date on May' 2025. Another letter sent to the client regarding the delay in response to swap the manufacturer on 08 Aug 2024. | I27: Close follow up with manufacturer to enhance delivery date. | J27: PM/Vendor | K27: 25/12/2025 as per supplier | L27: 46079 | M27: Open | N27: Schedule. 9 Months | O27: our schedule date in May, but the PO date in December, delivery now after our TCC
A28: PE-313 | B28: 4 | C28: Vendor | D28: Arteche | E28: 45704 | F28: The vendor of Free-Standing CT sent an email to delay the delivery to be on Mar’26 which scheduled to be on Jul’25 | G28: High | H28: The issue has been escalated to supply chain and supply chain sent official letter to the supplier. | I28: The supplier must follow the contractual delivery schedule. | J28: PM/Vendor | K28: 45851 | L28: 46098 | M28: Open | N28: Schedule. 8 Months | O28: After our TCC
A29: PE-313 | B29: 5 | C29: Vendor | D29: AES | E29: 45667 | F29: Delay in the confirmation date for FAT and delivery for the main Material and Equipment (SWGR, Station service TR, Panels, Protection, SAS, Communication) | G29: High | H29: Several mails has been sent to them requiring the FAT date Max by 1st of June | I29: Follow up with Vendoe to confirm the final date of delivery of every item | J29: PM | K29: 45762 | L29: 45823 | M29: Open
A30: PE-313 | B30: 5 | C30: Vendor | D30: EPC | E30: 45722 | F30: Delay in delivery of precast which scheduled to be delivered on Feb’25. | G30: Medium | H30: Warning email has been sent to the vendor on 10 Mar 2025 regarding the delay of manufacturing progress. | I30: Pushing the supplier to expedite in delivery of precast. | J30: PM/Vendor | K30: 45708 | L30: 45777 | M30: Open | N30: Schedule. 3 Months
A31: PE-325 | B31: 6 | C31: Vendor | D31: AES | E31: 45656 | F31: Delay from Alfanar factory in providing the designs and delivery date. Such as ( protection, SAS & telecom).​ | G31: High | H31: Arranged several meetings with AES and a warning letter has been issued. Telecom and Grounding situation has been enhanced. | I31: Close follow up on the remaining Points below: 1. Protection detail design and delivery 2. SAS sysetm Design and Delivery 3. Fault Locator Detail Design and Delivery | J31: PM/Vendor/Client | K31: 45672 | L31: 45729 | M31: Open | N31: 30 days delay
A32: PE-325 | B32: 9 | C32: Vendor | D32: AES | F32: No Confirmed date from AES for the FAT and Delivery date for Equipment (SWGR, SAS,MV Cables Protection, Telecom, Panels, Cyper Security) | G32: High | H32: Several Meetings arranged with AES to expedite design phases and Provide GAFM and now waiting for target dates for these Equipment | I32: High management follow up to get the delivery in line with the time schedule as they confirmed date by End of Aug while the planned is 15-Jul | J32: PM | K32: 45853 | L32: 45900 | M32: Open
A33: PE-325 | B33: 10 | C33: Vendor | D33: LAPP | E33: 45615 | F33: Insulators FAT schedule need to be enhanced from Dec’25 to Oct’2025.​ | G33: Medium | H33: 1. We have issued a letter to SEPDC with force major case due to the fire occurred at Lapp factory 2. Several meeting have been arranged with LAPP to reduce the delivery 3. Lapp confirmed the FAT by October 2025. | I33: Follow up and try to enhnace the delivery more if possible Delivery to be confirmed after GAFM after Plan & Profile approval. | J33: PM/Vendor | K33: 46021 | L33: 45735 | M33: Open | N33: schedule impact
