Workbook

Sheet Marketing-Related Sheet
A1: S.N. | B1: Project Code | C1: Project Name | D1: Project Managers Name | E1: Region | F1: Marketing Required (Yes/No) | G1: Requirement Provided (Yes/No) | H1: PO Creation (Yes/No) | I1: Marketing Completion (Yes/No) | J1: Required for Closing Projects (Yes/No/N/A) | K1: Start Date | L1: Planned % | M1: Actual % | N1: Var. | O1: Client | P1: City | Q1: EOT STATUS (Submitted/Approved/Under Approval/ N/A) | R1: TCC | U1: FAC | X1: Remarks
K2: Start Date | R2: Contract Date | S2: Revised Date | T2: Forecast Date | U2: Contract Date | V2: Revised Date | W2: Forecast Date | X2: Remarks
C3: CENTRAL REGION UNIT (BASIL ALHAKAMI)
A4: 1 | B4: PE-215 | C4: =VLOOKUP(B4,'Detailed Update'!B:C,2,FALSE) -> SMP - O&M 3 Yrs | D4: =VLOOKUP(B4,'Updated Progress % + TCC'!B:D,3,FALSE) -> Mohamed Sabri | E4: =VLOOKUP(B4,'Updated Progress % + TCC'!B:J,9,FALSE) -> Central | F4: =IF(M4>70.01%,"No","Yes") -> No | G4: No | H4: No | I4: No | K4: =VLOOKUP(B4,'Detailed Update'!B:D,3,FALSE) -> 44652 | L4: =VLOOKUP(B4,'Detailed Update'!B:I,4,FALSE) -> 1 | M4: =VLOOKUP(B4,'Detailed Update'!B:I,5,FALSE) -> 1 | N4: =M4-L4 -> 0 | O4: =VLOOKUP(B4,'Detailed Update'!B:I,6,FALSE) -> SEC | P4: =VLOOKUP(B4,'Detailed Update'!B:I,8,FALSE) -> Riyadh | Q4: Approved | R4: =VLOOKUP(B4,'Detailed Update'!B:T,11,FALSE) -> 45442 | S4: =VLOOKUP(B4,'Detailed Update'!B:T,12,FALSE) -> 45812 | T4: =VLOOKUP(B4,'Detailed Update'!B:T,13,FALSE) -> 45812 | U4: =VLOOKUP(B4,'Detailed Update'!B:T,17,FALSE) -> 45442 | V4: =VLOOKUP(B4,'Detailed Update'!B:S,18,FALSE) -> 45812 | W4: =VLOOKUP(B4,'Detailed Update'!B:T,19,FALSE) -> 45812 | X4: =VLOOKUP(B4,'Detailed Update'!B:U,20,FALSE) -> All certification Received
A5: 2 | B5: PE-226 | C5: =VLOOKUP(B5,'Detailed Update'!B:C,2,FALSE) -> KHASM-AL-AAN BSP | D5: =VLOOKUP(B5,'Updated Progress % + TCC'!B:D,3,FALSE) -> Amin El Sayed | E5: =VLOOKUP(B5,'Updated Progress % + TCC'!B:J,9,FALSE) -> Central | F5: =IF(M5>70.01%,"No","Yes") -> No | G5: No | H5: No | I5: No | K5: =VLOOKUP(B5,'Detailed Update'!B:D,3,FALSE) -> 44350 | L5: =VLOOKUP(B5,'Detailed Update'!B:I,4,FALSE) -> 1 | M5: =VLOOKUP(B5,'Detailed Update'!B:I,5,FALSE) -> 0.863 | N5: =M5-L5 -> -0.137 | O5: =VLOOKUP(B5,'Detailed Update'!B:I,6,FALSE) -> SEC | P5: =VLOOKUP(B5,'Detailed Update'!B:I,8,FALSE) -> Riyadh | Q5: Approved | R5: =VLOOKUP(B5,'Detailed Update'!B:T,11,FALSE) -> 44960 | S5: =VLOOKUP(B5,'Detailed Update'!B:T,12,FALSE) -> 45657 | T5: =VLOOKUP(B5,'Detailed Update'!B:T,13,FALSE) -> 46411 | U5: =VLOOKUP(B5,'Detailed Update'!B:T,17,FALSE) -> 45141 | V5: =VLOOKUP(B5,'Detailed Update'!B:S,18,FALSE) -> 45808 | W5: =VLOOKUP(B5,'Detailed Update'!B:T,19,FALSE) -> 46563 | X5: =VLOOKUP(B5,'Detailed Update'!B:U,20,FALSE) -> Partial TCC Received | Project on Hold
A6: 3 | B6: PM-223 | C6: =VLOOKUP(B6,'Detailed Update'!B:C,2,FALSE) -> GASCO - 2 | D6: =VLOOKUP(B6,'Updated Progress % + TCC'!B:D,3,FALSE) -> Fathi Mohamed | E6: =VLOOKUP(B6,'Updated Progress % + TCC'!B:J,9,FALSE) -> Central | F6: =IF(M6>70.01%,"No","Yes") -> No | G6: No | H6: No | I6: No | K6: =VLOOKUP(B6,'Detailed Update'!B:D,3,FALSE) -> 44368 | L6: =VLOOKUP(B6,'Detailed Update'!B:I,4,FALSE) -> 1 | M6: =VLOOKUP(B6,'Detailed Update'!B:I,5,FALSE) -> 0.9991 | N6: =M6-L6 -> -0.0009 | O6: =VLOOKUP(B6,'Detailed Update'!B:I,6,FALSE) -> GASCO | P6: =VLOOKUP(B6,'Detailed Update'!B:I,8,FALSE) -> Riyadh | Q6: Approved | R6: =VLOOKUP(B6,'Detailed Update'!B:T,11,FALSE) -> 45136 | S6: =VLOOKUP(B6,'Detailed Update'!B:T,12,FALSE) -> 45747 | T6: =VLOOKUP(B6,'Detailed Update'!B:T,13,FALSE) -> 45961 | U6: =VLOOKUP(B6,'Detailed Update'!B:T,17,FALSE) -> 45136 | V6: =VLOOKUP(B6,'Detailed Update'!B:S,18,FALSE) -> 45747 | W6: =VLOOKUP(B6,'Detailed Update'!B:T,19,FALSE) -> 45961 | X6: =VLOOKUP(B6,'Detailed Update'!B:U,20,FALSE) -> Initial Handing over received
A7: 4 | B7: PE-228 | C7: =VLOOKUP(B7,'Detailed Update'!B:C,2,FALSE) -> SVC QASSIM -2 | D7: =VLOOKUP(B7,'Updated Progress % + TCC'!B:D,3,FALSE) -> Hany Kamal | E7: =VLOOKUP(B7,'Updated Progress % + TCC'!B:J,9,FALSE) -> Central | F7: =IF(M7>70.01%,"No","Yes") -> No | G7: No | H7: No | I7: No | K7: =VLOOKUP(B7,'Detailed Update'!B:D,3,FALSE) -> 44444 | L7: =VLOOKUP(B7,'Detailed Update'!B:I,4,FALSE) -> 1 | M7: =VLOOKUP(B7,'Detailed Update'!B:I,5,FALSE) -> 0.9928 | N7: =M7-L7 -> -0.0072 | O7: =VLOOKUP(B7,'Detailed Update'!B:I,6,FALSE) -> SEC | P7: =VLOOKUP(B7,'Detailed Update'!B:I,8,FALSE) -> Riyadh | Q7: Approved | R7: =VLOOKUP(B7,'Detailed Update'!B:T,11,FALSE) -> 45235 | S7: =VLOOKUP(B7,'Detailed Update'!B:T,12,FALSE) -> 45733 | T7: =VLOOKUP(B7,'Detailed Update'!B:T,13,FALSE) -> 45733 | U7: =VLOOKUP(B7,'Detailed Update'!B:T,17,FALSE) -> 45356 | V7: =VLOOKUP(B7,'Detailed Update'!B:S,18,FALSE) -> 45855 | W7: =VLOOKUP(B7,'Detailed Update'!B:T,19,FALSE) -> 46264 | X7: =VLOOKUP(B7,'Detailed Update'!B:U,20,FALSE) -> TCC Received.
A8: 5 | B8: PE-233 | C8: =VLOOKUP(B8,'Detailed Update'!B:C,2,FALSE) -> Tabarjal 380KV BSP Expn. | D8: =VLOOKUP(B8,'Updated Progress % + TCC'!B:D,3,FALSE) -> Malik Qarioutyee | E8: =VLOOKUP(B8,'Updated Progress % + TCC'!B:J,9,FALSE) -> Central | F8: =IF(M8>70.01%,"No","Yes") -> No | G8: No | H8: No | I8: No | K8: =VLOOKUP(B8,'Detailed Update'!B:D,3,FALSE) -> 44542 | L8: =VLOOKUP(B8,'Detailed Update'!B:I,4,FALSE) -> 1 | M8: =VLOOKUP(B8,'Detailed Update'!B:I,5,FALSE) -> 0.99 | N8: =M8-L8 -> -0.01 | O8: =VLOOKUP(B8,'Detailed Update'!B:I,6,FALSE) -> SEC | P8: =VLOOKUP(B8,'Detailed Update'!B:I,8,FALSE) -> Riyadh | Q8: Approved | R8: =VLOOKUP(B8,'Detailed Update'!B:T,11,FALSE) -> 45272 | S8: =VLOOKUP(B8,'Detailed Update'!B:T,12,FALSE) -> 46021 | T8: =VLOOKUP(B8,'Detailed Update'!B:T,13,FALSE) -> 46233 | U8: =VLOOKUP(B8,'Detailed Update'!B:T,17,FALSE) -> 45424 | V8: =VLOOKUP(B8,'Detailed Update'!B:S,18,FALSE) -> 46172 | W8: =VLOOKUP(B8,'Detailed Update'!B:T,19,FALSE) -> 46386 | X8: =VLOOKUP(B8,'Detailed Update'!B:U,20,FALSE) -> Partial TCC received on 16-Jan-24
A9: 6 | B9: PE-245 | C9: =VLOOKUP(B9,'Detailed Update'!B:C,2,FALSE) -> Hail OHTL | D9: =VLOOKUP(B9,'Updated Progress % + TCC'!B:D,3,FALSE) -> Rafa Awad Al Hassan | E9: =VLOOKUP(B9,'Updated Progress % + TCC'!B:J,9,FALSE) -> Central | F9: =IF(M9>70.01%,"No","Yes") -> No | G9: No | H9: No | I9: No | K9: =VLOOKUP(B9,'Detailed Update'!B:D,3,FALSE) -> 44788 | L9: =VLOOKUP(B9,'Detailed Update'!B:I,4,FALSE) -> 1 | M9: =VLOOKUP(B9,'Detailed Update'!B:I,5,FALSE) -> 0.9612 | N9: =M9-L9 -> -0.0388 | O9: =VLOOKUP(B9,'Detailed Update'!B:I,6,FALSE) -> SEC | P9: =VLOOKUP(B9,'Detailed Update'!B:I,8,FALSE) -> Riyadh | Q9: Approved | R9: =VLOOKUP(B9,'Detailed Update'!B:T,11,FALSE) -> 45427 | S9: =VLOOKUP(B9,'Detailed Update'!B:T,12,FALSE) -> 45656 | T9: =VLOOKUP(B9,'Detailed Update'!B:T,13,FALSE) -> 46193 | U9: =VLOOKUP(B9,'Detailed Update'!B:T,17,FALSE) -> 45580 | V9: =VLOOKUP(B9,'Detailed Update'!B:S,18,FALSE) -> 45804 | W9: =VLOOKUP(B9,'Detailed Update'!B:T,19,FALSE) -> 46341 | X9: =VLOOKUP(B9,'Detailed Update'!B:U,20,FALSE) -> One line Energizaed. Another line by 20-Jun-26. Change Order approval is critical
A10: 7 | B10: PE-247 | C10: =VLOOKUP(B10,'Detailed Update'!B:C,2,FALSE) -> RIYADH SEDRA-2 | D10: =VLOOKUP(B10,'Updated Progress % + TCC'!B:D,3,FALSE) -> Anas Derzy | E10: =VLOOKUP(B10,'Updated Progress % + TCC'!B:J,9,FALSE) -> Central | F10: =IF(M10>70.01%,"No","Yes") -> No | G10: No | H10: No | I10: No | K10: =VLOOKUP(B10,'Detailed Update'!B:D,3,FALSE) -> 44833 | L10: =VLOOKUP(B10,'Detailed Update'!B:I,4,FALSE) -> 1 | M10: =VLOOKUP(B10,'Detailed Update'!B:I,5,FALSE) -> 0.991 | N10: =M10-L10 -> -0.009 | O10: =VLOOKUP(B10,'Detailed Update'!B:I,6,FALSE) -> Roshn | P10: =VLOOKUP(B10,'Detailed Update'!B:I,8,FALSE) -> Riyadh | Q10: Under Approval | R10: =VLOOKUP(B10,'Detailed Update'!B:T,11,FALSE) -> 45538 | S10: =VLOOKUP(B10,'Detailed Update'!B:T,12,FALSE) -> 45538 | T10: =VLOOKUP(B10,'Detailed Update'!B:T,13,FALSE) -> 45920 | U10: =VLOOKUP(B10,'Detailed Update'!B:T,17,FALSE) -> 45599 | V10: =VLOOKUP(B10,'Detailed Update'!B:S,18,FALSE) -> 45599 | W10: =VLOOKUP(B10,'Detailed Update'!B:T,19,FALSE) -> 46264 | X10: =VLOOKUP(B10,'Detailed Update'!B:U,20,FALSE) -> Partial TCC received & 90% invoice approved
A11: 8 | B11: PE-248 | C11: =VLOOKUP(B11,'Detailed Update'!B:C,2,FALSE) -> PP10 Conv. | D11: =VLOOKUP(B11,'Updated Progress % + TCC'!B:D,3,FALSE) -> Rabei Mohamed Mohamed Attia Daoud | E11: =VLOOKUP(B11,'Updated Progress % + TCC'!B:J,9,FALSE) -> Central | F11: =IF(M11>70.01%,"No","Yes") -> No | G11: No | H11: No | I11: No | K11: =VLOOKUP(B11,'Detailed Update'!B:D,3,FALSE) -> 44847 | L11: =VLOOKUP(B11,'Detailed Update'!B:I,4,FALSE) -> 1 | M11: =VLOOKUP(B11,'Detailed Update'!B:I,5,FALSE) -> 0.9576 | N11: =M11-L11 -> -0.0424 | O11: =VLOOKUP(B11,'Detailed Update'!B:I,6,FALSE) -> SEC | P11: =VLOOKUP(B11,'Detailed Update'!B:I,8,FALSE) -> Riyadh | Q11: Approved | R11: =VLOOKUP(B11,'Detailed Update'!B:T,11,FALSE) -> 45517 | S11: =VLOOKUP(B11,'Detailed Update'!B:T,12,FALSE) -> 46018 | T11: =VLOOKUP(B11,'Detailed Update'!B:T,13,FALSE) -> 46263 | U11: =VLOOKUP(B11,'Detailed Update'!B:T,17,FALSE) -> 45974 | V11: =VLOOKUP(B11,'Detailed Update'!B:S,18,FALSE) -> 46477 | W11: =VLOOKUP(B11,'Detailed Update'!B:T,19,FALSE) -> 46720 | X11: =VLOOKUP(B11,'Detailed Update'!B:U,20,FALSE) -> TCC milestone achieved. Certification not receied. Punchlist Clearance is critical
A12: 9 | B12: PE-255 | C12: =VLOOKUP(B12,'Detailed Update'!B:C,2,FALSE) -> 380kv D/C OHTL LILO SAAD OHTL | D12: =VLOOKUP(B12,'Updated Progress % + TCC'!B:D,3,FALSE) -> Malik Al Qaryotee | E12: =VLOOKUP(B12,'Updated Progress % + TCC'!B:J,9,FALSE) -> Central | F12: =IF(M12>70.01%,"No","Yes") -> No | G12: Yes | K12: =VLOOKUP(B12,'Detailed Update'!B:D,3,FALSE) -> 44857 | L12: =VLOOKUP(B12,'Detailed Update'!B:I,4,FALSE) -> 0.8998 | M12: =VLOOKUP(B12,'Detailed Update'!B:I,5,FALSE) -> 0.7518 | N12: =M12-L12 -> -0.148 | O12: =VLOOKUP(B12,'Detailed Update'!B:I,6,FALSE) -> SEC | P12: =VLOOKUP(B12,'Detailed Update'!B:I,8,FALSE) -> Riyadh | Q12: Approved | R12: =VLOOKUP(B12,'Detailed Update'!B:T,11,FALSE) -> 45283 | S12: =VLOOKUP(B12,'Detailed Update'!B:T,12,FALSE) -> 45813 | T12: =VLOOKUP(B12,'Detailed Update'!B:T,13,FALSE) -> 46386 | U12: =VLOOKUP(B12,'Detailed Update'!B:T,17,FALSE) -> 45466 | V12: =VLOOKUP(B12,'Detailed Update'!B:S,18,FALSE) -> 45996 | W12: =VLOOKUP(B12,'Detailed Update'!B:T,19,FALSE) -> 46569 | X12: =VLOOKUP(B12,'Detailed Update'!B:U,20,FALSE) -> 1. Amendment for New circuit Arrangement at Tapping Point . 2. Outage requirements 3. Hardware fittings material for re-route portion
A13: 10 | B13: PE-256 | C13: =VLOOKUP(B13,'Detailed Update'!B:C,2,FALSE) -> Sudair PV 380KV BSP | D13: =VLOOKUP(B13,'Updated Progress % + TCC'!B:D,3,FALSE) -> Tariq Mahmoud Ali Alsheyab | E13: =VLOOKUP(B13,'Updated Progress % + TCC'!B:J,9,FALSE) -> Central | F13: =IF(M13>70.01%,"No","Yes") -> No | G13: No | H13: No | I13: No | K13: =VLOOKUP(B13,'Detailed Update'!B:D,3,FALSE) -> 44867 | L13: =VLOOKUP(B13,'Detailed Update'!B:I,4,FALSE) -> 1 | M13: =VLOOKUP(B13,'Detailed Update'!B:I,5,FALSE) -> 0.7877 | N13: =M13-L13 -> -0.2123 | O13: =VLOOKUP(B13,'Detailed Update'!B:I,6,FALSE) -> SEC | P13: =VLOOKUP(B13,'Detailed Update'!B:I,8,FALSE) -> Riyadh | Q13: Under Approval | R13: =VLOOKUP(B13,'Detailed Update'!B:T,11,FALSE) -> 45537 | S13: =VLOOKUP(B13,'Detailed Update'!B:T,12,FALSE) -> 45537 | T13: =VLOOKUP(B13,'Detailed Update'!B:T,13,FALSE) -> 46325 | U13: =VLOOKUP(B13,'Detailed Update'!B:T,17,FALSE) -> 45690 | V13: =VLOOKUP(B13,'Detailed Update'!B:S,18,FALSE) -> 45690 | W13: =VLOOKUP(B13,'Detailed Update'!B:T,19,FALSE) -> 46478 | X13: =VLOOKUP(B13,'Detailed Update'!B:U,20,FALSE) -> SS portion energized. Delay in Receiving Permit UGC works and inside PP9 works (MTO,LOA& ARAMCO Permits)
A14: 11 | B14: PE-259 | C14: =VLOOKUP(B14,'Detailed Update'!B:C,2,FALSE) -> WAAD AL SHAMAAL 380KV BSP | D14: =VLOOKUP(B14,'Updated Progress % + TCC'!B:D,3,FALSE) -> Muhannad Ibrahim Al Heh | E14: =VLOOKUP(B14,'Updated Progress % + TCC'!B:J,9,FALSE) -> Central | F14: =IF(M14>70.01%,"No","Yes") -> No | G14: No | H14: No | I14: No | K14: =VLOOKUP(B14,'Detailed Update'!B:D,3,FALSE) -> 44871 | L14: =VLOOKUP(B14,'Detailed Update'!B:I,4,FALSE) -> 1 | M14: =VLOOKUP(B14,'Detailed Update'!B:I,5,FALSE) -> 0.9693 | N14: =M14-L14 -> -0.0307 | O14: =VLOOKUP(B14,'Detailed Update'!B:I,6,FALSE) -> SEC | P14: =VLOOKUP(B14,'Detailed Update'!B:I,8,FALSE) -> Riyadh | Q14: Approved | R14: =VLOOKUP(B14,'Detailed Update'!B:T,11,FALSE) -> 45611 | S14: =VLOOKUP(B14,'Detailed Update'!B:T,12,FALSE) -> 45807 | T14: =VLOOKUP(B14,'Detailed Update'!B:T,13,FALSE) -> 46356 | U14: =VLOOKUP(B14,'Detailed Update'!B:T,17,FALSE) -> 45762 | V14: =VLOOKUP(B14,'Detailed Update'!B:S,18,FALSE) -> 45960 | W14: =VLOOKUP(B14,'Detailed Update'!B:T,19,FALSE) -> 46509 | X14: =VLOOKUP(B14,'Detailed Update'!B:U,20,FALSE) -> Paritally Energized on 09-Feb-26 | Delay in receiving outage to enrgize CKT 2 Wind to Waad Alshamaal & Wind to TABARJAL energization (expected by Oct 26)
A15: 12 | B15: PE-264 | C15: =VLOOKUP(B15,'Detailed Update'!B:C,2,FALSE) -> TABARJAL-B 13213.8 KV S/S IN JOUF | D15: =VLOOKUP(B15,'Updated Progress % + TCC'!B:D,3,FALSE) -> Khalid Mohamed Aql | E15: =VLOOKUP(B15,'Updated Progress % + TCC'!B:J,9,FALSE) -> Central | F15: =IF(M15>70.01%,"No","Yes") -> No | G15: No | H15: No | I15: No | K15: =VLOOKUP(B15,'Detailed Update'!B:D,3,FALSE) -> 45063 | L15: =VLOOKUP(B15,'Detailed Update'!B:I,4,FALSE) -> 1 | M15: =VLOOKUP(B15,'Detailed Update'!B:I,5,FALSE) -> 0.9918 | N15: =M15-L15 -> -0.0082 | O15: =VLOOKUP(B15,'Detailed Update'!B:I,6,FALSE) -> SEC | P15: =VLOOKUP(B15,'Detailed Update'!B:I,8,FALSE) -> Riyadh | Q15: Approved | R15: =VLOOKUP(B15,'Detailed Update'!B:T,11,FALSE) -> 45732 | S15: =VLOOKUP(B15,'Detailed Update'!B:T,12,FALSE) -> 45838 | T15: =VLOOKUP(B15,'Detailed Update'!B:T,13,FALSE) -> 46202 | U15: =VLOOKUP(B15,'Detailed Update'!B:T,17,FALSE) -> 45885 | V15: =VLOOKUP(B15,'Detailed Update'!B:S,18,FALSE) -> 45991 | W15: =VLOOKUP(B15,'Detailed Update'!B:T,19,FALSE) -> 46355 | X15: =VLOOKUP(B15,'Detailed Update'!B:U,20,FALSE) -> 1.Total of four circuits are planned; two are scheduled for energization by June 2026. 2.SE confirmation is still pending for the remaining two circuits.
A16: 13 | B16: PE-271 | C16: =VLOOKUP(B16,'Detailed Update'!B:C,2,FALSE) -> AL-DAR AL-BAIDHA 132/13.8KV SUB | D16: =VLOOKUP(B16,'Updated Progress % + TCC'!B:D,3,FALSE) -> Hassan Ayloti | E16: =VLOOKUP(B16,'Updated Progress % + TCC'!B:J,9,FALSE) -> Central | F16: =IF(M16>70.01%,"No","Yes") -> No | G16: No | H16: No | I16: No | K16: =VLOOKUP(B16,'Detailed Update'!B:D,3,FALSE) -> 45120 | L16: =VLOOKUP(B16,'Detailed Update'!B:I,4,FALSE) -> 1 | M16: =VLOOKUP(B16,'Detailed Update'!B:I,5,FALSE) -> 0.985 | N16: =M16-L16 -> -0.015 | O16: =VLOOKUP(B16,'Detailed Update'!B:I,6,FALSE) -> SEC | P16: =VLOOKUP(B16,'Detailed Update'!B:I,8,FALSE) -> Riyadh | Q16: Approved | R16: =VLOOKUP(B16,'Detailed Update'!B:T,11,FALSE) -> 45608 | S16: =VLOOKUP(B16,'Detailed Update'!B:T,12,FALSE) -> 46081 | T16: =VLOOKUP(B16,'Detailed Update'!B:T,13,FALSE) -> 46098 | U16: =VLOOKUP(B16,'Detailed Update'!B:T,17,FALSE) -> 45759 | V16: =VLOOKUP(B16,'Detailed Update'!B:S,18,FALSE) -> 46231 | W16: =VLOOKUP(B16,'Detailed Update'!B:T,19,FALSE) -> 46416 | X16: =VLOOKUP(B16,'Detailed Update'!B:U,20,FALSE) -> Energized on 17-Mar-26 | Other Circuit depends on Outage | Expected - 31-Oct-26
A17: 14 | B17: PE-272 | C17: =VLOOKUP(B17,'Detailed Update'!B:C,2,FALSE) -> AL-MUNSIYAH 132/13.8KV SUB # 8273 | D17: =VLOOKUP(B17,'Updated Progress % + TCC'!B:D,3,FALSE) -> Mohamed El hag | E17: =VLOOKUP(B17,'Updated Progress % + TCC'!B:J,9,FALSE) -> Central | F17: =IF(M17>70.01%,"No","Yes") -> No | G17: No | H17: No | I17: No | K17: =VLOOKUP(B17,'Detailed Update'!B:D,3,FALSE) -> 45120 | L17: =VLOOKUP(B17,'Detailed Update'!B:I,4,FALSE) -> 1 | M17: =VLOOKUP(B17,'Detailed Update'!B:I,5,FALSE) -> 0.9613 | N17: =M17-L17 -> -0.0387 | O17: =VLOOKUP(B17,'Detailed Update'!B:I,6,FALSE) -> SEC | P17: =VLOOKUP(B17,'Detailed Update'!B:I,8,FALSE) -> Riyadh | Q17: Under Approval | R17: =VLOOKUP(B17,'Detailed Update'!B:T,11,FALSE) -> 45609 | S17: =VLOOKUP(B17,'Detailed Update'!B:T,12,FALSE) -> 45609 | T17: =VLOOKUP(B17,'Detailed Update'!B:T,13,FALSE) -> 46272 | U17: =VLOOKUP(B17,'Detailed Update'!B:T,17,FALSE) -> 45760 | V17: =VLOOKUP(B17,'Detailed Update'!B:S,18,FALSE) -> 45760 | W17: =VLOOKUP(B17,'Detailed Update'!B:T,19,FALSE) -> 46423 | X17: =VLOOKUP(B17,'Detailed Update'!B:U,20,FALSE) -> One Circuit Energized. Other Circuit depends on Outage | Expected - 31-Oct-26
A18: 15 | B18: PE-273 | C18: =VLOOKUP(B18,'Detailed Update'!B:C,2,FALSE) -> ALMANFOHA 132/13.8KV SUB # 8138 | D18: =VLOOKUP(B18,'Updated Progress % + TCC'!B:D,3,FALSE) -> Mohamed El hag | E18: =VLOOKUP(B18,'Updated Progress % + TCC'!B:J,9,FALSE) -> Central | F18: =IF(M18>70.01%,"No","Yes") -> No | G18: No | H18: No | I18: No | K18: =VLOOKUP(B18,'Detailed Update'!B:D,3,FALSE) -> 45119 | L18: =VLOOKUP(B18,'Detailed Update'!B:I,4,FALSE) -> 1 | M18: =VLOOKUP(B18,'Detailed Update'!B:I,5,FALSE) -> 0.986 | N18: =M18-L18 -> -0.014 | O18: =VLOOKUP(B18,'Detailed Update'!B:I,6,FALSE) -> SEC | P18: =VLOOKUP(B18,'Detailed Update'!B:I,8,FALSE) -> Riyadh | Q18: Under Approval | R18: =VLOOKUP(B18,'Detailed Update'!B:T,11,FALSE) -> 45608 | S18: =VLOOKUP(B18,'Detailed Update'!B:T,12,FALSE) -> 45991 | T18: =VLOOKUP(B18,'Detailed Update'!B:T,13,FALSE) -> 45991 | U18: =VLOOKUP(B18,'Detailed Update'!B:T,17,FALSE) -> 45759 | V18: =VLOOKUP(B18,'Detailed Update'!B:S,18,FALSE) -> 46142 | W18: =VLOOKUP(B18,'Detailed Update'!B:T,19,FALSE) -> 46415 | X18: =VLOOKUP(B18,'Detailed Update'!B:U,20,FALSE) -> One Circuit Energized on 21-Dec-25
A19: 16 | B19: PE-274 | C19: =VLOOKUP(B19,'Detailed Update'!B:C,2,FALSE) -> NASIRIYAH 132/13.8KV SUB # 8154 | D19: =VLOOKUP(B19,'Updated Progress % + TCC'!B:D,3,FALSE) -> Omar Samman | E19: =VLOOKUP(B19,'Updated Progress % + TCC'!B:J,9,FALSE) -> Central | F19: =IF(M19>70.01%,"No","Yes") -> No | G19: No | H19: No | I19: No | K19: =VLOOKUP(B19,'Detailed Update'!B:D,3,FALSE) -> 45119 | L19: =VLOOKUP(B19,'Detailed Update'!B:I,4,FALSE) -> 1 | M19: =VLOOKUP(B19,'Detailed Update'!B:I,5,FALSE) -> 0.927 | N19: =M19-L19 -> -0.073 | O19: =VLOOKUP(B19,'Detailed Update'!B:I,6,FALSE) -> SEC | P19: =VLOOKUP(B19,'Detailed Update'!B:I,8,FALSE) -> Riyadh | Q19: Approved | R19: =VLOOKUP(B19,'Detailed Update'!B:T,11,FALSE) -> 45608 | S19: =VLOOKUP(B19,'Detailed Update'!B:T,12,FALSE) -> 46034 | T19: =VLOOKUP(B19,'Detailed Update'!B:T,13,FALSE) -> 46022 | U19: =VLOOKUP(B19,'Detailed Update'!B:T,17,FALSE) -> 45759 | V19: =VLOOKUP(B19,'Detailed Update'!B:S,18,FALSE) -> 46185 | W19: =VLOOKUP(B19,'Detailed Update'!B:T,19,FALSE) -> 46295 | X19: =VLOOKUP(B19,'Detailed Update'!B:U,20,FALSE) -> One Energized on 11-Feb-26. TCC received with dated 31-Dec-2025
A20: 17 | B20: PE-275 | C20: =VLOOKUP(B20,'Detailed Update'!B:C,2,FALSE) -> 380kV Diriyah Gate-2 BSP # 9080 | D20: =VLOOKUP(B20,'Updated Progress % + TCC'!B:D,3,FALSE) -> Amin El Sayed | E20: =VLOOKUP(B20,'Updated Progress % + TCC'!B:J,9,FALSE) -> Central | F20: =IF(M20>70.01%,"No","Yes") -> Yes | I20: yes | K20: =VLOOKUP(B20,'Detailed Update'!B:D,3,FALSE) -> 45246 | L20: =VLOOKUP(B20,'Detailed Update'!B:I,4,FALSE) -> 0.5084 | M20: =VLOOKUP(B20,'Detailed Update'!B:I,5,FALSE) -> 0.4512 | N20: =M20-L20 -> -0.0572 | O20: =VLOOKUP(B20,'Detailed Update'!B:I,6,FALSE) -> SEC | P20: =VLOOKUP(B20,'Detailed Update'!B:I,8,FALSE) -> Riyadh | Q20: Under Approval | R20: =VLOOKUP(B20,'Detailed Update'!B:T,11,FALSE) -> 45977 | S20: =VLOOKUP(B20,'Detailed Update'!B:T,12,FALSE) -> 46490 | T20: =VLOOKUP(B20,'Detailed Update'!B:T,13,FALSE) -> 46547 | U20: =VLOOKUP(B20,'Detailed Update'!B:T,17,FALSE) -> 46128 | V20: =VLOOKUP(B20,'Detailed Update'!B:S,18,FALSE) -> 46641 | W20: =VLOOKUP(B20,'Detailed Update'!B:T,19,FALSE) -> 46698 | X20: =VLOOKUP(B20,'Detailed Update'!B:U,20,FALSE) -> Progress based on Internal Baseline. 1-Delay in approval of water proofing VO & removal of loose material, which affects the construction works. 2- Negative Cash flow. 3-Claim Approval 201 Mn for prolongation & inflation costs. 4- Delivery for disconnector switch expected to be delayed.
A21: 18 | B21: PE-276 | C21: =VLOOKUP(B21,'Detailed Update'!B:C,2,FALSE) -> SHARAFIYAH 380 KV SS | D21: =VLOOKUP(B21,'Updated Progress % + TCC'!B:D,3,FALSE) -> Mohamed Sabri | E21: =VLOOKUP(B21,'Updated Progress % + TCC'!B:J,9,FALSE) -> Central | F21: =IF(M21>70.01%,"No","Yes") -> No | G21: No | H21: No | I21: No | K21: =VLOOKUP(B21,'Detailed Update'!B:D,3,FALSE) -> 45139 | L21: =VLOOKUP(B21,'Detailed Update'!B:I,4,FALSE) -> 1 | M21: =VLOOKUP(B21,'Detailed Update'!B:I,5,FALSE) -> 0.9378 | N21: =M21-L21 -> -0.0622 | O21: =VLOOKUP(B21,'Detailed Update'!B:I,6,FALSE) -> SEC | P21: =VLOOKUP(B21,'Detailed Update'!B:I,8,FALSE) -> Riyadh | Q21: Under Approval | R21: =VLOOKUP(B21,'Detailed Update'!B:T,11,FALSE) -> 45689 | S21: =VLOOKUP(B21,'Detailed Update'!B:T,12,FALSE) -> 45689 | T21: =VLOOKUP(B21,'Detailed Update'!B:T,13,FALSE) -> 46183 | U21: =VLOOKUP(B21,'Detailed Update'!B:T,17,FALSE) -> 45839 | V21: =VLOOKUP(B21,'Detailed Update'!B:S,18,FALSE) -> 45839 | W21: =VLOOKUP(B21,'Detailed Update'!B:T,19,FALSE) -> 46333 | X21: =VLOOKUP(B21,'Detailed Update'!B:U,20,FALSE) -> Partially Energized. 1.Taihan - Oil Joints 2.Design Approval - 6 Remote end ( 132 kV) 3.Gantry Foundation for Existing Substation 4.Unclear Shutdown schedule for Power and Communication link with all remote ends 5. Delay in Micro Trenching of FOC 25km
A22: 19 | B22: PE-279 | C22: =VLOOKUP(B22,'Detailed Update'!B:C,2,FALSE) -> AL-NAZEEM 132/13.8KV SS # 8271 | D22: =VLOOKUP(B22,'Updated Progress % + TCC'!B:D,3,FALSE) -> Nedal Alkhatib | E22: =VLOOKUP(B22,'Updated Progress % + TCC'!B:J,9,FALSE) -> Central | F22: =IF(M22>70.01%,"No","Yes") -> No | G22: No | H22: No | I22: No | K22: =VLOOKUP(B22,'Detailed Update'!B:D,3,FALSE) -> 45131 | L22: =VLOOKUP(B22,'Detailed Update'!B:I,4,FALSE) -> 1 | M22: =VLOOKUP(B22,'Detailed Update'!B:I,5,FALSE) -> 0.9085 | N22: =M22-L22 -> -0.0915 | O22: =VLOOKUP(B22,'Detailed Update'!B:I,6,FALSE) -> SEC | P22: =VLOOKUP(B22,'Detailed Update'!B:I,8,FALSE) -> Riyadh | Q22: Approved | R22: =VLOOKUP(B22,'Detailed Update'!B:T,11,FALSE) -> 45619 | S22: =VLOOKUP(B22,'Detailed Update'!B:T,12,FALSE) -> 45831 | T22: =VLOOKUP(B22,'Detailed Update'!B:T,13,FALSE) -> 46387 | U22: =VLOOKUP(B22,'Detailed Update'!B:T,17,FALSE) -> 45770 | V22: =VLOOKUP(B22,'Detailed Update'!B:S,18,FALSE) -> 45984 | W22: =VLOOKUP(B22,'Detailed Update'!B:T,19,FALSE) -> 46540 | X22: =VLOOKUP(B22,'Detailed Update'!B:U,20,FALSE) -> Commissioing on Hold due to non-readiness of UG Contractor
A23: 20 | B23: PE-299 | C23: =VLOOKUP(B23,'Detailed Update'!B:C,2,FALSE) -> Reinf of 132KV Network of Baqaa | D23: =VLOOKUP(B23,'Updated Progress % + TCC'!B:D,3,FALSE) -> Yousef AlMohtaseb | E23: =VLOOKUP(B23,'Updated Progress % + TCC'!B:J,9,FALSE) -> Central | F23: =IF(M23>70.01%,"No","Yes") -> No | G23: No | H23: No | I23: No | K23: =VLOOKUP(B23,'Detailed Update'!B:D,3,FALSE) -> 45238 | L23: =VLOOKUP(B23,'Detailed Update'!B:I,4,FALSE) -> 0.9992 | M23: =VLOOKUP(B23,'Detailed Update'!B:I,5,FALSE) -> 0.9358 | N23: =M23-L23 -> -0.0634 | O23: =VLOOKUP(B23,'Detailed Update'!B:I,6,FALSE) -> SEC | P23: =VLOOKUP(B23,'Detailed Update'!B:I,8,FALSE) -> Riyadh | Q23: Approved | R23: =VLOOKUP(B23,'Detailed Update'!B:T,11,FALSE) -> 45784 | S23: =VLOOKUP(B23,'Detailed Update'!B:T,12,FALSE) -> 45981 | T23: =VLOOKUP(B23,'Detailed Update'!B:T,13,FALSE) -> 46326 | U23: =VLOOKUP(B23,'Detailed Update'!B:T,17,FALSE) -> 45937 | V23: =VLOOKUP(B23,'Detailed Update'!B:S,18,FALSE) -> 46132 | W23: =VLOOKUP(B23,'Detailed Update'!B:T,19,FALSE) -> 46477 | X23: =VLOOKUP(B23,'Detailed Update'!B:U,20,FALSE) -> 1.OHTL S/C & D/C crossing - Delay in HOT permits 2.Cutting point outage at TEE OFF location. 3.ERS System & TEE- OFF Tower Installation 4.Design Approval of Flood Protection
A24: 21 | B24: PE-300 | C24: =VLOOKUP(B24,'Detailed Update'!B:C,2,FALSE) -> 300 MVAR STATCOM | D24: =VLOOKUP(B24,'Updated Progress % + TCC'!B:D,3,FALSE) -> Ibrahim Jaradat | E24: =VLOOKUP(B24,'Updated Progress % + TCC'!B:J,9,FALSE) -> Central | F24: =IF(M24>70.01%,"No","Yes") -> Yes | G24: no | K24: =VLOOKUP(B24,'Detailed Update'!B:D,3,FALSE) -> 45357 | L24: =VLOOKUP(B24,'Detailed Update'!B:I,4,FALSE) -> 0.7928 | M24: =VLOOKUP(B24,'Detailed Update'!B:I,5,FALSE) -> 0.6916 | N24: =M24-L24 -> -0.1012 | O24: =VLOOKUP(B24,'Detailed Update'!B:I,6,FALSE) -> SEC | P24: =VLOOKUP(B24,'Detailed Update'!B:I,8,FALSE) -> Riyadh | Q24: Under Approval | R24: =VLOOKUP(B24,'Detailed Update'!B:T,11,FALSE) -> 46087 | S24: =VLOOKUP(B24,'Detailed Update'!B:T,12,FALSE) -> 46271 | T24: =VLOOKUP(B24,'Detailed Update'!B:T,13,FALSE) -> 46315 | U24: =VLOOKUP(B24,'Detailed Update'!B:T,17,FALSE) -> 46240 | V24: =VLOOKUP(B24,'Detailed Update'!B:S,18,FALSE) -> 46059 | W24: =VLOOKUP(B24,'Detailed Update'!B:T,19,FALSE) -> 46103 | X24: =VLOOKUP(B24,'Detailed Update'!B:U,20,FALSE) -> 1.Delay in delivery of AES scope material. (delay in these materials ,impact the project completion ) 2.Delay in 380 kv insulator (Lapp) 3.New fire pump-Delivery (change order), 4.Delay in delivery of MV grounding transformer
A25: 22 | B25: PE-306 | C25: =VLOOKUP(B25,'Detailed Update'!B:C,2,FALSE) -> NEW AL-ARED 380/132KV BSP | D25: =VLOOKUP(B25,'Updated Progress % + TCC'!B:D,3,FALSE) -> Munther Elkhatib | E25: =VLOOKUP(B25,'Updated Progress % + TCC'!B:J,9,FALSE) -> Central | F25: =IF(M25>70.01%,"No","Yes") -> No | G25: No | H25: No | I25: No | K25: =VLOOKUP(B25,'Detailed Update'!B:D,3,FALSE) -> 45218 | L25: =VLOOKUP(B25,'Detailed Update'!B:I,4,FALSE) -> 1 | M25: =VLOOKUP(B25,'Detailed Update'!B:I,5,FALSE) -> 0.9468 | N25: =M25-L25 -> -0.0532 | O25: =VLOOKUP(B25,'Detailed Update'!B:I,6,FALSE) -> SEC | P25: =VLOOKUP(B25,'Detailed Update'!B:I,8,FALSE) -> Riyadh | Q25: Under Approval | R25: =VLOOKUP(B25,'Detailed Update'!B:T,11,FALSE) -> 45766 | S25: =VLOOKUP(B25,'Detailed Update'!B:T,12,FALSE) -> 45888 | T25: =VLOOKUP(B25,'Detailed Update'!B:T,13,FALSE) -> 46203 | U25: =VLOOKUP(B25,'Detailed Update'!B:T,17,FALSE) -> 45919 | V25: =VLOOKUP(B25,'Detailed Update'!B:S,18,FALSE) -> 46041 | W25: =VLOOKUP(B25,'Detailed Update'!B:T,19,FALSE) -> 46356 | X25: =VLOOKUP(B25,'Detailed Update'!B:U,20,FALSE) -> 1.Slow Punch list - Transformers ,GIS, AES 2.Delay in SEC UG Cable Vendor - New Line( Circuits 3 )
A26: 23 | B26: PE-309 | C26: =VLOOKUP(B26,'Detailed Update'!B:C,2,FALSE) -> Reliablity Enh.for SS of 9011 in Sudair | D26: =VLOOKUP(B26,'Updated Progress % + TCC'!B:D,3,FALSE) -> Mohsin Arshad | E26: =VLOOKUP(B26,'Updated Progress % + TCC'!B:J,9,FALSE) -> Central | F26: =IF(M26>70.01%,"No","Yes") -> Yes | G26: =IF(N26>70.01%,"No","Yes") -> Yes | K26: =VLOOKUP(B26,'Detailed Update'!B:D,3,FALSE) -> 46015 | L26: =VLOOKUP(B26,'Detailed Update'!B:I,4,FALSE) -> 0.4504 | M26: =VLOOKUP(B26,'Detailed Update'!B:I,5,FALSE) -> 0.2189 | N26: =M26-L26 -> -0.2315 | O26: =VLOOKUP(B26,'Detailed Update'!B:I,6,FALSE) -> SEC | P26: =VLOOKUP(B26,'Detailed Update'!B:I,8,FALSE) -> Riyadh | Q26: N/A | R26: =VLOOKUP(B26,'Detailed Update'!B:T,11,FALSE) -> 46349 | S26: =VLOOKUP(B26,'Detailed Update'!B:T,12,FALSE) -> 46349 | T26: =VLOOKUP(B26,'Detailed Update'!B:T,13,FALSE) -> 46498 | U26: =VLOOKUP(B26,'Detailed Update'!B:T,17,FALSE) -> 46500 | V26: =VLOOKUP(B26,'Detailed Update'!B:S,18,FALSE) -> 46500 | W26: =VLOOKUP(B26,'Detailed Update'!B:T,19,FALSE) -> 46649 | X26: =VLOOKUP(B26,'Detailed Update'!B:U,20,FALSE) -> Current issues 1.Delay in Plan & Profile - OHTL 2.Delay in Plan & Profile - UG Cable ( T- off Tower Location) 3.Delay in SE supply GIS Bays 4.Delay in Material :- Tower, Hardware, Insulator 5. Delay in providing existing Design : Remote End, U/G 8500 to 8521, Basement & Sleeves Details, Telecom Room, Control Room Layouts 6.Delay in Mobilization of Project Team OHTL Site Engr & Project Engr, QA & QC Civil & Electrical 7. Unclear Shutdown for Project
A27: 24 | B27: PE-310 | C27: =VLOOKUP(B27,'Detailed Update'!B:C,2,FALSE) -> Al Shifa Housing 132/13.8KV SS | D27: =VLOOKUP(B27,'Updated Progress % + TCC'!B:D,3,FALSE) -> Meshari Alqarni | E27: =VLOOKUP(B27,'Updated Progress % + TCC'!B:J,9,FALSE) -> Central | F27: =IF(M27>70.01%,"No","Yes") -> No | G27: No | H27: No | I27: No | K27: =VLOOKUP(B27,'Detailed Update'!B:D,3,FALSE) -> 45313 | L27: =VLOOKUP(B27,'Detailed Update'!B:I,4,FALSE) -> 0.946 | M27: =VLOOKUP(B27,'Detailed Update'!B:I,5,FALSE) -> 0.8692 | N27: =M27-L27 -> -0.0768 | O27: =VLOOKUP(B27,'Detailed Update'!B:I,6,FALSE) -> SEC | P27: =VLOOKUP(B27,'Detailed Update'!B:I,8,FALSE) -> Riyadh | Q27: Under Approval | R27: =VLOOKUP(B27,'Detailed Update'!B:T,11,FALSE) -> 45983 | S27: =VLOOKUP(B27,'Detailed Update'!B:T,12,FALSE) -> 46194 | T27: =VLOOKUP(B27,'Detailed Update'!B:T,13,FALSE) -> 46251 | U27: =VLOOKUP(B27,'Detailed Update'!B:T,17,FALSE) -> 46133 | V27: =VLOOKUP(B27,'Detailed Update'!B:S,18,FALSE) -> 46347 | W27: =VLOOKUP(B27,'Detailed Update'!B:T,19,FALSE) -> 46404 | X27: =VLOOKUP(B27,'Detailed Update'!B:U,20,FALSE) -> 1.Incomplete HV underground cable works under another contractor’s scope are impacting the substation energization activities. 2.STATCOM PQS approval remains pending with SEC/vendor, affecting material delivery and subsequent installation. 3.Delay in remote end (8131) works due to pending C1 work permit
A28: 25 | B28: PE-326 | C28: =VLOOKUP(B28,'Detailed Update'!B:C,2,FALSE) -> Shaqra Wind 380/132kV SS | D28: =VLOOKUP(B28,'Updated Progress % + TCC'!B:D,3,FALSE) -> Ahmed Mosaad Abdel Nabi Hussein | E28: =VLOOKUP(B28,'Updated Progress % + TCC'!B:J,9,FALSE) -> Central | F28: =IF(M28>70.01%,"No","Yes") -> Yes | G28: no | K28: =VLOOKUP(B28,'Detailed Update'!B:D,3,FALSE) -> 45589 | L28: =VLOOKUP(B28,'Detailed Update'!B:I,4,FALSE) -> 0.9675 | M28: =VLOOKUP(B28,'Detailed Update'!B:I,5,FALSE) -> 0.6877 | N28: =M28-L28 -> -0.2798 | O28: =VLOOKUP(B28,'Detailed Update'!B:I,6,FALSE) -> SEC | P28: =VLOOKUP(B28,'Detailed Update'!B:I,8,FALSE) -> Riyadh | Q28: N/A | R28: =VLOOKUP(B28,'Detailed Update'!B:T,11,FALSE) -> 46165 | S28: =VLOOKUP(B28,'Detailed Update'!B:T,12,FALSE) -> 46165 | T28: =VLOOKUP(B28,'Detailed Update'!B:T,13,FALSE) -> 46387 | U28: =VLOOKUP(B28,'Detailed Update'!B:T,17,FALSE) -> 46318 | V28: =VLOOKUP(B28,'Detailed Update'!B:S,18,FALSE) -> 46318 | W28: =VLOOKUP(B28,'Detailed Update'!B:T,19,FALSE) -> 46540 | X28: =VLOOKUP(B28,'Detailed Update'!B:U,20,FALSE) -> 1-Delay in the delivery of 132kV and 380kV GIB and Hybrid GIS (SEC Direct purchase) beyond the scheduled dates, where the original plan was December 2025; however, only the 132kV GIB was delivered in end of May 2026, while the 380kV GIB and Hybrid GIS are still pending. 2-Delay in the supply of AC and DC panels from AES up to date. 3- Delay in obtaining ITP approvals for DSM and TFR systems AES prequalification to perform the FAT in AES factory. 4-Change order confirmation for the additional scope , which holding following activities (Civil work for Search facilities - Guard house - security building and along with all septic tank and water connections , HCIS stage 3 finalization and approval , Procurement of all electrical , mechanical , security material related to this pending . 5-Delay in the approval of firefighting system designs due to changing multiple changes in the review process from SEC and adding new comments with each revision. 6- After approval of lightening panels design (MS Hawaa ) SEC insist to change the manufactural to new alternate as (MS hawaa )is currently suspended in the system 7- Confirmation of EOT which submitted 9-Apr-26.
A29: 26 | B29: PE-335 | C29: =VLOOKUP(B29,'Detailed Update'!B:C,2,FALSE) -> Battery Energy (BESS) - Qaisumah | D29: =VLOOKUP(B29,'Updated Progress % + TCC'!B:D,3,FALSE) -> Tariq Mahmoud Ali Alsheyab | E29: =VLOOKUP(B29,'Updated Progress % + TCC'!B:J,9,FALSE) -> Central | F29: =IF(M29>70.01%,"No","Yes") -> No | G29: No | H29: No | I29: No | K29: =VLOOKUP(B29,'Detailed Update'!B:D,3,FALSE) -> 45642 | L29: =VLOOKUP(B29,'Detailed Update'!B:I,4,FALSE) -> 1 | M29: =VLOOKUP(B29,'Detailed Update'!B:I,5,FALSE) -> 0.9563 | N29: =M29-L29 -> -0.0437 | O29: =VLOOKUP(B29,'Detailed Update'!B:I,6,FALSE) -> SEC | P29: =VLOOKUP(B29,'Detailed Update'!B:I,8,FALSE) -> Riyadh | Q29: N/A | R29: =VLOOKUP(B29,'Detailed Update'!B:T,11,FALSE) -> 46158 | S29: =VLOOKUP(B29,'Detailed Update'!B:T,12,FALSE) -> 46158 | T29: =VLOOKUP(B29,'Detailed Update'!B:T,13,FALSE) -> 46153 | U29: =VLOOKUP(B29,'Detailed Update'!B:T,17,FALSE) -> 46311 | V29: =VLOOKUP(B29,'Detailed Update'!B:S,18,FALSE) -> 46311 | W29: =VLOOKUP(B29,'Detailed Update'!B:T,19,FALSE) -> 46306 | X29: =VLOOKUP(B29,'Detailed Update'!B:U,20,FALSE) -> Energized.
A30: 27 | B30: PE-336 | C30: =VLOOKUP(B30,'Detailed Update'!B:C,2,FALSE) -> Battery Energy (BESS) - Dawadmi | D30: =VLOOKUP(B30,'Updated Progress % + TCC'!B:D,3,FALSE) -> Mohamed Ahmed Abdellatif Abdelkader | E30: =VLOOKUP(B30,'Updated Progress % + TCC'!B:J,9,FALSE) -> Central | F30: =IF(M30>70.01%,"No","Yes") -> No | G30: No | H30: No | I30: No | K30: =VLOOKUP(B30,'Detailed Update'!B:D,3,FALSE) -> 45642 | L30: =VLOOKUP(B30,'Detailed Update'!B:I,4,FALSE) -> 1 | M30: =VLOOKUP(B30,'Detailed Update'!B:I,5,FALSE) -> 0.9766 | N30: =M30-L30 -> -0.0234 | O30: =VLOOKUP(B30,'Detailed Update'!B:I,6,FALSE) -> SEC | P30: =VLOOKUP(B30,'Detailed Update'!B:I,8,FALSE) -> Riyadh | Q30: N/A | R30: =VLOOKUP(B30,'Detailed Update'!B:T,11,FALSE) -> 46158 | S30: =VLOOKUP(B30,'Detailed Update'!B:T,12,FALSE) -> 46158 | T30: =VLOOKUP(B30,'Detailed Update'!B:T,13,FALSE) -> 46152 | U30: =VLOOKUP(B30,'Detailed Update'!B:T,17,FALSE) -> 46311 | V30: =VLOOKUP(B30,'Detailed Update'!B:S,18,FALSE) -> 46311 | W30: =VLOOKUP(B30,'Detailed Update'!B:T,19,FALSE) -> 46305 | X30: =VLOOKUP(B30,'Detailed Update'!B:U,20,FALSE) -> Energized.
A31: 28 | B31: PE-337 | C31: =VLOOKUP(B31,'Detailed Update'!B:C,2,FALSE) -> Battery Energy (BESS) - Airport | D31: =VLOOKUP(B31,'Updated Progress % + TCC'!B:D,3,FALSE) -> Tarig Mohammed | E31: =VLOOKUP(B31,'Updated Progress % + TCC'!B:J,9,FALSE) -> Central | F31: =IF(M31>70.01%,"No","Yes") -> No | G31: No | H31: No | I31: No | K31: =VLOOKUP(B31,'Detailed Update'!B:D,3,FALSE) -> 45642 | L31: =VLOOKUP(B31,'Detailed Update'!B:I,4,FALSE) -> 1 | M31: =VLOOKUP(B31,'Detailed Update'!B:I,5,FALSE) -> 0.9883 | N31: =M31-L31 -> -0.0117 | O31: =VLOOKUP(B31,'Detailed Update'!B:I,6,FALSE) -> SEC | P31: =VLOOKUP(B31,'Detailed Update'!B:I,8,FALSE) -> Riyadh | Q31: N/A | R31: =VLOOKUP(B31,'Detailed Update'!B:T,11,FALSE) -> 46158 | S31: =VLOOKUP(B31,'Detailed Update'!B:T,12,FALSE) -> 46158 | T31: =VLOOKUP(B31,'Detailed Update'!B:T,13,FALSE) -> 46148 | U31: =VLOOKUP(B31,'Detailed Update'!B:T,17,FALSE) -> 46311 | V31: =VLOOKUP(B31,'Detailed Update'!B:S,18,FALSE) -> 46311 | W31: =VLOOKUP(B31,'Detailed Update'!B:T,19,FALSE) -> 46301 | X31: =VLOOKUP(B31,'Detailed Update'!B:U,20,FALSE) -> Energized.
A32: 29 | B32: PE-339 | C32: =VLOOKUP(B32,'Detailed Update'!B:C,2,FALSE) -> Battery Energy (BESS) - Jouf | D32: =VLOOKUP(B32,'Updated Progress % + TCC'!B:D,3,FALSE) -> Khalid Mohamed Aql | E32: =VLOOKUP(B32,'Updated Progress % + TCC'!B:J,9,FALSE) -> Central | F32: =IF(M32>70.01%,"No","Yes") -> No | G32: No | H32: No | I32: No | K32: =VLOOKUP(B32,'Detailed Update'!B:D,3,FALSE) -> 45642 | L32: =VLOOKUP(B32,'Detailed Update'!B:I,4,FALSE) -> 1 | M32: =VLOOKUP(B32,'Detailed Update'!B:I,5,FALSE) -> 0.9862 | N32: =M32-L32 -> -0.0138 | O32: =VLOOKUP(B32,'Detailed Update'!B:I,6,FALSE) -> SEC | P32: =VLOOKUP(B32,'Detailed Update'!B:I,8,FALSE) -> Jouf | Q32: N/A | R32: =VLOOKUP(B32,'Detailed Update'!B:T,11,FALSE) -> 46158 | S32: =VLOOKUP(B32,'Detailed Update'!B:T,12,FALSE) -> 46158 | T32: =VLOOKUP(B32,'Detailed Update'!B:T,13,FALSE) -> 46158 | U32: =VLOOKUP(B32,'Detailed Update'!B:T,17,FALSE) -> 46311 | V32: =VLOOKUP(B32,'Detailed Update'!B:S,18,FALSE) -> 46311 | W32: =VLOOKUP(B32,'Detailed Update'!B:T,19,FALSE) -> 46311 | X32: =VLOOKUP(B32,'Detailed Update'!B:U,20,FALSE) -> Energized.
A33: 30 | B33: PE-348 | C33: =VLOOKUP(B33,'Detailed Update'!B:C,2,FALSE) -> Construction of Hail-2 Substation for BESS | D33: =VLOOKUP(B33,'Updated Progress % + TCC'!B:D,3,FALSE) -> Muhannad Ibrahim Al Heh | E33: =VLOOKUP(B33,'Updated Progress % + TCC'!B:J,9,FALSE) -> Central | F33: =IF(M33>70.01%,"No","Yes") -> Yes | G33: No | K33: =VLOOKUP(B33,'Detailed Update'!B:D,3,FALSE) -> 45841 | L33: =VLOOKUP(B33,'Detailed Update'!B:I,4,FALSE) -> 0.8873 | M33: =VLOOKUP(B33,'Detailed Update'!B:I,5,FALSE) -> 0.4661 | N33: =M33-L33 -> -0.4212 | O33: =VLOOKUP(B33,'Detailed Update'!B:I,6,FALSE) -> SEC | P33: =VLOOKUP(B33,'Detailed Update'!B:I,8,FALSE) -> Hail | Q33: N/A | R33: =VLOOKUP(B33,'Detailed Update'!B:T,11,FALSE) -> 46176 | S33: =VLOOKUP(B33,'Detailed Update'!B:T,12,FALSE) -> 46176 | T33: =VLOOKUP(B33,'Detailed Update'!B:T,13,FALSE) -> 46280 | U33: =VLOOKUP(B33,'Detailed Update'!B:T,17,FALSE) -> 46329 | V33: =VLOOKUP(B33,'Detailed Update'!B:S,18,FALSE) -> 46329 | W33: =VLOOKUP(B33,'Detailed Update'!B:T,19,FALSE) -> 46433 | X33: =VLOOKUP(B33,'Detailed Update'!B:U,20,FALSE) -> 1-Delay in approving critical designs such as FF designs, & Remote end AMI , with some submittals open for more than 3 months 2- Delay in design inputs has delayed grid studies submission & approval cycles 3- Delay in Alfanar equipment delivery: - Auxiliary transformer - AC & DC Panels - TFR & DSM - Remote End AMI & Metering 4- Delay in BESS Supplier fire fighting protion delivery (BESS gas pipes) 5- Delay in Firefighting pumps delivery 6- Delay in surge arrestors, and post insulators delivery 7- Delay in 33Kv SWGR termination kits delivery 8- Delay in HGIS Delivery: 1 out of 2 Bays delivered 9- Delay in UPS delivery
A34: 31 | B34: PE-353 | C34: =VLOOKUP(B34,'Detailed Update'!B:C,2,FALSE) -> Conv of Riyadh CC PP10 - Phase 2 | D34: =VLOOKUP(B34,'Updated Progress % + TCC'!B:D,3,FALSE) -> Muhannad Badawi | E34: =VLOOKUP(B34,'Updated Progress % + TCC'!B:J,9,FALSE) -> Central | F34: =IF(M34>70.01%,"No","Yes") -> Yes | G34: =IF(N34>70.01%,"No","Yes") -> Yes | K34: =VLOOKUP(B34,'Detailed Update'!B:D,3,FALSE) -> 45785 | L34: =VLOOKUP(B34,'Detailed Update'!B:I,4,FALSE) -> 0.4019 | M34: =VLOOKUP(B34,'Detailed Update'!B:I,5,FALSE) -> 0.1642 | N34: =M34-L34 -> -0.2377 | O34: =VLOOKUP(B34,'Detailed Update'!B:I,6,FALSE) -> SEC | P34: =VLOOKUP(B34,'Detailed Update'!B:I,8,FALSE) -> Riyadh | Q34: N/A | R34: =VLOOKUP(B34,'Detailed Update'!B:T,11,FALSE) -> 46515 | S34: =VLOOKUP(B34,'Detailed Update'!B:T,12,FALSE) -> 46515 | T34: =VLOOKUP(B34,'Detailed Update'!B:T,13,FALSE) -> 46765 | U34: =VLOOKUP(B34,'Detailed Update'!B:T,17,FALSE) -> 46912 | V34: =VLOOKUP(B34,'Detailed Update'!B:S,18,FALSE) -> 46912 | W34: =VLOOKUP(B34,'Detailed Update'!B:T,19,FALSE) -> 47162 | X34: =VLOOKUP(B34,'Detailed Update'!B:U,20,FALSE) -> 1.Base Design Approval : Disagreement with SE on interpretation of the Contract. 2.Engineering Review Cycle Delays : Agreed timelines for review are not being adhered. 3.Delivery durations for critical (LLIs) exceed the Contractual timeline, creating a significant risk to meeting the contractual milestones. 4.Accelerated Dec 2026 completion requested by SE for GT 1st Fire. 5.Site Access Gate Permits & Work Permit issues.
A35: 32 | B35: PE-356 | C35: =VLOOKUP(B35,'Detailed Update'!B:C,2,FALSE) -> 380KV OHTL | MAWQAQ BSP CONNECTION | D35: =VLOOKUP(B35,'Updated Progress % + TCC'!B:D,3,FALSE) -> Omar Samman | E35: =VLOOKUP(B35,'Updated Progress % + TCC'!B:J,9,FALSE) -> Central | F35: =IF(M35>70.01%,"No","Yes") -> Yes | G35: no | K35: =VLOOKUP(B35,'Detailed Update'!B:D,3,FALSE) -> 45897 | L35: =VLOOKUP(B35,'Detailed Update'!B:I,4,FALSE) -> 0.5331 | M35: =VLOOKUP(B35,'Detailed Update'!B:I,5,FALSE) -> 0.1606 | N35: =M35-L35 -> -0.3725 | O35: =VLOOKUP(B35,'Detailed Update'!B:I,6,FALSE) -> SEC | P35: =VLOOKUP(B35,'Detailed Update'!B:I,8,FALSE) -> Riyadh | Q35: N/A | R35: =VLOOKUP(B35,'Detailed Update'!B:T,11,FALSE) -> 46446 | S35: =VLOOKUP(B35,'Detailed Update'!B:T,12,FALSE) -> 46446 | T35: =VLOOKUP(B35,'Detailed Update'!B:T,13,FALSE) -> 46723 | U35: =VLOOKUP(B35,'Detailed Update'!B:T,17,FALSE) -> 46595 | V35: =VLOOKUP(B35,'Detailed Update'!B:S,18,FALSE) -> 46595 | W35: =VLOOKUP(B35,'Detailed Update'!B:T,19,FALSE) -> 46873 | X35: =VLOOKUP(B35,'Detailed Update'!B:U,20,FALSE) -> 1) Revised Route with additional change order.Revised Route under approval 2) Finalization of the route is pending for the portion that falls under KSRR. 3) Cost and time impact resulting from the increased transmission line route length and associated scope changes. 4) Delay in approval of plan and profile
A36: 33 | B36: PE-360 | C36: =VLOOKUP(B36,'Detailed Update'!B:C,2,FALSE) -> SMP|OPERATION & PROF. SERVICES (HES&HHU) | D36: =VLOOKUP(B36,'Updated Progress % + TCC'!B:D,3,FALSE) -> Hazem Mahmoud | E36: =VLOOKUP(B36,'Updated Progress % + TCC'!B:J,9,FALSE) -> Central | F36: =IF(M36>70.01%,"No","Yes") -> No | K36: =VLOOKUP(B36,'Detailed Update'!B:D,3,FALSE) -> 45853 | L36: =VLOOKUP(B36,'Detailed Update'!B:I,4,FALSE) -> 0.8333 | M36: =VLOOKUP(B36,'Detailed Update'!B:I,5,FALSE) -> 0.8333 | N36: =M36-L36 -> 0 | O36: =VLOOKUP(B36,'Detailed Update'!B:I,6,FALSE) -> SEC | P36: =VLOOKUP(B36,'Detailed Update'!B:I,8,FALSE) -> Riyadh | Q36: N/A | R36: =VLOOKUP(B36,'Detailed Update'!B:T,11,FALSE) -> 46217 | S36: =VLOOKUP(B36,'Detailed Update'!B:T,12,FALSE) -> 46309 | T36: =VLOOKUP(B36,'Detailed Update'!B:T,13,FALSE) -> 46309 | U36: =VLOOKUP(B36,'Detailed Update'!B:T,17,FALSE) -> 46217 | V36: =VLOOKUP(B36,'Detailed Update'!B:S,18,FALSE) -> 46309 | W36: =VLOOKUP(B36,'Detailed Update'!B:T,19,FALSE) -> 46309 | X36: =VLOOKUP(B36,'Detailed Update'!B:U,20,FALSE) -> Extension of 1 quarter received
A37: 34 | B37: PE-362 | C37: =VLOOKUP(B37,'Detailed Update'!B:C,2,FALSE) -> 132KV SS |CONST. SPORTS BOULEVARD-RIYADH | D37: =VLOOKUP(B37,'Updated Progress % + TCC'!B:D,3,FALSE) -> Mirza Ikramullah | E37: =VLOOKUP(B37,'Updated Progress % + TCC'!B:J,9,FALSE) -> Central | F37: =IF(M37>70.01%,"No","Yes") -> Yes | G37: No | K37: =VLOOKUP(B37,'Detailed Update'!B:D,3,FALSE) -> 45882 | L37: =VLOOKUP(B37,'Detailed Update'!B:I,4,FALSE) -> 0.3324 | M37: =VLOOKUP(B37,'Detailed Update'!B:I,5,FALSE) -> 0.2194 | N37: =M37-L37 -> -0.113 | O37: =VLOOKUP(B37,'Detailed Update'!B:I,6,FALSE) -> SEC | P37: =VLOOKUP(B37,'Detailed Update'!B:I,8,FALSE) -> Riyadh | Q37: N/A | R37: =VLOOKUP(B37,'Detailed Update'!B:T,11,FALSE) -> 46429 | S37: =VLOOKUP(B37,'Detailed Update'!B:T,12,FALSE) -> 46429 | T37: =VLOOKUP(B37,'Detailed Update'!B:T,13,FALSE) -> 46660 | U37: =VLOOKUP(B37,'Detailed Update'!B:T,17,FALSE) -> 46579 | V37: =VLOOKUP(B37,'Detailed Update'!B:S,18,FALSE) -> 46579 | W37: =VLOOKUP(B37,'Detailed Update'!B:T,19,FALSE) -> 46810 | X37: =VLOOKUP(B37,'Detailed Update'!B:U,20,FALSE) -> Delay in Site Handing Over. Not handed over yet
A38: 35 | B38: PE-316 | C38: =VLOOKUP(B38,'Detailed Update'!B:C,2,FALSE) -> HVDC-1 | COA-WOA | RUH-9022 | D38: =VLOOKUP(B38,'Updated Progress % + TCC'!B:D,3,FALSE) -> Mohamed Sabri | E38: =VLOOKUP(B38,'Updated Progress % + TCC'!B:J,9,FALSE) -> Central | F38: =IF(M38>70.01%,"No","Yes") -> Yes | H38: =IF(O38>70.01%,"No","Yes") -> No | I38: =IF(P38>70.01%,"No","Yes") -> No | K38: =VLOOKUP(B38,'Detailed Update'!B:D,3,FALSE) -> 45470 | L38: =VLOOKUP(B38,'Detailed Update'!B:I,4,FALSE) -> 0.7932 | M38: =VLOOKUP(B38,'Detailed Update'!B:I,5,FALSE) -> 0.6971 | N38: =M38-L38 -> -0.0961 | O38: =VLOOKUP(B38,'Detailed Update'!B:I,6,FALSE) -> SEC | P38: =VLOOKUP(B38,'Detailed Update'!B:I,8,FALSE) -> Riyadh | Q38: N/A | R38: =VLOOKUP(B38,'Detailed Update'!B:T,11,FALSE) -> 46387 | S38: =VLOOKUP(B38,'Detailed Update'!B:T,12,FALSE) -> 46387 | T38: =VLOOKUP(B38,'Detailed Update'!B:T,13,FALSE) -> 46418 | U38: =VLOOKUP(B38,'Detailed Update'!B:T,17,FALSE) -> 46538 | V38: =VLOOKUP(B38,'Detailed Update'!B:S,18,FALSE) -> 46538 | W38: =VLOOKUP(B38,'Detailed Update'!B:T,19,FALSE) -> 46569 | X38: =VLOOKUP(B38,'Detailed Update'!B:U,20,FALSE) -> -
A39: 36 | B39: PE-317 | C39: =VLOOKUP(B39,'Detailed Update'!B:C,2,FALSE) -> HVDC-2 | COA-SOA | RUH-9041 | D39: =VLOOKUP(B39,'Updated Progress % + TCC'!B:D,3,FALSE) -> Mohamed Sabri | E39: =VLOOKUP(B39,'Updated Progress % + TCC'!B:J,9,FALSE) -> Central | F39: =IF(M39>70.01%,"No","Yes") -> No | I39: yes | K39: =VLOOKUP(B39,'Detailed Update'!B:D,3,FALSE) -> 45470 | L39: =VLOOKUP(B39,'Detailed Update'!B:I,4,FALSE) -> 0.8948 | M39: =VLOOKUP(B39,'Detailed Update'!B:I,5,FALSE) -> 0.7873 | N39: =M39-L39 -> -0.1075 | O39: =VLOOKUP(B39,'Detailed Update'!B:I,6,FALSE) -> SEC | P39: =VLOOKUP(B39,'Detailed Update'!B:I,8,FALSE) -> Riyadh | Q39: N/A | R39: =VLOOKUP(B39,'Detailed Update'!B:T,11,FALSE) -> 46387 | S39: =VLOOKUP(B39,'Detailed Update'!B:T,12,FALSE) -> 46387 | T39: =VLOOKUP(B39,'Detailed Update'!B:T,13,FALSE) -> 46446 | U39: =VLOOKUP(B39,'Detailed Update'!B:T,17,FALSE) -> 46538 | V39: =VLOOKUP(B39,'Detailed Update'!B:S,18,FALSE) -> 46538 | W39: =VLOOKUP(B39,'Detailed Update'!B:T,19,FALSE) -> 46597 | X39: =VLOOKUP(B39,'Detailed Update'!B:U,20,FALSE) -> -
A40: 37 | B40: PE-363 | C40: =VLOOKUP(B40,'Detailed Update'!B:C,2,FALSE) -> SULYBIAH SS 8823 132/33KV | D40: =VLOOKUP(B40,'Updated Progress % + TCC'!B:D,3,FALSE) -> Youssef Al Mohtaesab | E40: =VLOOKUP(B40,'Updated Progress % + TCC'!B:J,9,FALSE) -> Central | F40: =IF(M40>70.01%,"No","Yes") -> Yes | K40: =VLOOKUP(B40,'Detailed Update'!B:D,3,FALSE) -> 46047 | L40: =VLOOKUP(B40,'Detailed Update'!B:I,4,FALSE) -> 0.0505 | M40: =VLOOKUP(B40,'Detailed Update'!B:I,5,FALSE) -> 0.0342 | N40: =M40-L40 -> -0.0163 | O40: =VLOOKUP(B40,'Detailed Update'!B:I,6,FALSE) -> SEC | P40: =VLOOKUP(B40,'Detailed Update'!B:I,8,FALSE) -> Qassim | Q40: N/A | R40: =VLOOKUP(B40,'Detailed Update'!B:T,11,FALSE) -> 46593 | S40: =VLOOKUP(B40,'Detailed Update'!B:T,12,FALSE) -> 46593 | T40: =VLOOKUP(B40,'Detailed Update'!B:T,13,FALSE) -> 46673 | U40: =VLOOKUP(B40,'Detailed Update'!B:T,17,FALSE) -> 46746 | V40: =VLOOKUP(B40,'Detailed Update'!B:S,18,FALSE) -> 46746 | W40: =VLOOKUP(B40,'Detailed Update'!B:T,19,FALSE) -> 46826 | X40: =VLOOKUP(B40,'Detailed Update'!B:U,20,FALSE) -> 1. Delay in Receiving Design for GIS Package Supplied by SEC Vendor 2. Delay in soil investigation activities due to one corner of the substation located on farmland 3. Terminal compound 1 location changed 4. Repetition of soil investigation activities due to the client's rejection of the proposed vendor
...

Sheet Detailed Update
B1: Project Code | C1: Project Name | D1: Start Date | E1: Planned % | F1: Actual % | G1: Client | H1: Region | I1: City | J1: Latest EOT approved Date | K1: EOT STATUS (Submitted/Approved/Under Approval/ N/A) | M1: TCC | P1: PAC | R1: FAC / Overall Project | U1: Remarks
D2: Start Date | L2: TCC | M2: Revised Date | N2: Forecast Date | O2: Contract Date | P2: Revised Date | Q2: Forecast Date | R2: Contract Date | S2: Revised Date | T2: Forecast Date
C3: CENTRAL REGION UNIT
A4: 1 | B4: PE-215 | C4: SMP - O&M 3 Yrs | D4: 44652 | E4: 1 | F4: 1 | G4: SEC | H4: Central | I4: Riyadh | K4: Approved | L4: 45442 | M4: 45812 | N4: 45812 | O4: 45442 | P4: 45812 | Q4: 45812 | R4: 45442 | S4: 45812 | T4: 45812 | U4: All certification Received
A5: =A4+1 -> 2 | B5: PE-226 | C5: KHASM-AL-AAN BSP | D5: 44350 | E5: 1 | F5: 0.863 | G5: SEC | H5: Central | I5: Riyadh | J5: 45386 | K5: Approved | L5: 44960 | M5: 45657 | N5: 46411 | O5: 45049 | P5: 45716 | Q5: =N5+60 -> 46471 | R5: 45141 | S5: 45808 | T5: =Q5+(S5-P5) -> 46563 | U5: Partial TCC Received | Project on Hold
A6: =A5+1 -> 3 | B6: PM-223 | C6: GASCO - 2 | D6: 44368 | E6: 1 | F6: 0.9991 | G6: GASCO | H6: Central | I6: Riyadh | K6: Approved | L6: 45136 | M6: 45747 | N6: 45961 | O6: 45136 | P6: 45747 | Q6: 45961 | R6: 45136 | S6: 45747 | T6: 45961 | U6: Initial Handing over received
A7: =A6+1 -> 4 | B7: PE-228 | C7: SVC QASSIM -2 | D7: 44444 | E7: 1 | F7: 0.9928 | G7: SEC | H7: Central | I7: Riyadh | K7: Approved | L7: 45235 | M7: 45733 | N7: 45733 | O7: 45296 | P7: 45794 | Q7: 46203 | R7: 45356 | S7: 45855 | T7: =Q7+(S7-P7) -> 46264 | U7: TCC Received.
A8: =A7+1 -> 5 | B8: PE-233 | C8: Tabarjal 380KV BSP Expn. | D8: 44542 | E8: 1 | F8: 0.99 | G8: SEC | H8: Central | I8: Riyadh | K8: Approved | L8: 45272 | M8: 46021 | N8: 46233 | O8: 45334 | P8: 46081 | Q8: 46295 | R8: 45424 | S8: 46172 | T8: =Q8+(S8-P8) -> 46386 | U8: Partial TCC received on 16-Jan-24
A9: =A8+1 -> 6 | B9: PE-245 | C9: Hail OHTL | D9: 44788 | E9: 1 | F9: 0.9612 | G9: SEC | H9: Central | I9: Riyadh | J9: 45476 | K9: Approved | L9: 45427 | M9: 45656 | N9: 46193 | O9: 45488 | P9: 45716 | Q9: =N9+60 -> 46253 | R9: 45580 | S9: 45804 | T9: =Q9+(S9-P9) -> 46341 | U9: One line Energizaed. Another line by 20-Jun-26. Change Order approval is critical
A10: =A9+1 -> 7 | B10: PE-247 | C10: RIYADH SEDRA-2 | D10: 44833 | E10: 1 | F10: 0.991 | G10: Roshn | H10: Central | I10: Riyadh | K10: Under Approval | L10: 45538 | M10: 45538 | N10: 45920 | O10: 45568 | P10: 45568 | Q10: 46233 | R10: 45599 | S10: 45599 | T10: =Q10+(S10-P10) -> 46264 | U10: Partial TCC received & 90% invoice approved
A11: =A10+1 -> 8 | B11: PE-248 | C11: PP10 Conv. | D11: 44847 | E11: 1 | F11: 0.9576 | G11: SEC | H11: Central | I11: Riyadh | J11: 45553 | K11: Approved | L11: 45517 | M11: 46018 | N11: 46263 | O11: 45609 | P11: 46112 | Q11: 46355 | R11: 45974 | S11: 46477 | T11: =Q11+(S11-P11) -> 46720 | U11: TCC milestone achieved. Certification not receied. Punchlist Clearance is critical
A12: =A11+1 -> 9 | B12: PE-255 | C12: 380kv D/C OHTL LILO SAAD OHTL | D12: 44857 | E12: 0.8998 | F12: 0.7518 | G12: SEC | H12: Central | I12: Riyadh | J12: 45449 | K12: Approved | L12: 45283 | M12: 45813 | N12: 46386 | O12: 45374 | P12: 45905 | Q12: =N12+(P12-M12) -> 46478 | R12: 45466 | S12: 45996 | T12: =Q12+(S12-P12) -> 46569 | U12: 1. Amendment for New circuit Arrangement at Tapping Point . 2. Outage requirements 3. Hardware fittings material for re-route portion
A13: =A12+1 -> 10 | B13: PE-256 | C13: Sudair PV 380KV BSP | D13: 44867 | E13: 1 | F13: 0.7877 | G13: SEC | H13: Central | I13: Riyadh | K13: Under Approval | L13: 45537 | M13: 45537 | N13: 46325 | O13: 45598 | P13: 45598 | Q13: =N13+(P13-M13) -> 46386 | R13: 45690 | S13: 45690 | T13: =Q13+(S13-P13) -> 46478 | U13: SS portion energized. Delay in Receiving Permit UGC works and inside PP9 works (MTO,LOA& ARAMCO Permits)
A14: =A13+1 -> 11 | B14: PE-259 | C14: WAAD AL SHAMAAL 380KV BSP | D14: 44871 | E14: 1 | F14: 0.9693 | G14: SEC | H14: Central | I14: Riyadh | K14: Approved | L14: 45611 | M14: 45807 | N14: 46356 | O14: 45672 | P14: 45868 | Q14: =N14+(P14-M14) -> 46417 | R14: 45762 | S14: 45960 | T14: =Q14+(S14-P14) -> 46509 | U14: Paritally Energized on 09-Feb-26 | Delay in receiving outage to enrgize CKT 2 Wind to Waad Alshamaal & Wind to TABARJAL energization (expected by Oct 26)
A15: =A14+1 -> 12 | B15: PE-264 | C15: TABARJAL-B 13213.8 KV S/S IN JOUF | D15: 45063 | E15: 1 | F15: 0.9918 | G15: SEC | H15: Central | I15: Riyadh | K15: Approved | L15: 45732 | M15: 45838 | N15: 46202 | O15: 45793 | P15: 45899 | Q15: =N15+(P15-M15) -> 46263 | R15: 45885 | S15: 45991 | T15: =Q15+(S15-P15) -> 46355 | U15: 1.Total of four circuits are planned; two are scheduled for energization by June 2026. 2.SE confirmation is still pending for the remaining two circuits.
A16: =A15+1 -> 13 | B16: PE-271 | C16: AL-DAR AL-BAIDHA 132/13.8KV SUB | D16: 45120 | E16: 1 | F16: 0.985 | G16: SEC | H16: Central | I16: Riyadh | J16: 46039 | K16: Approved | L16: 45608 | M16: 46081 | N16: 46098 | O16: 45669 | P16: 46140 | Q16: 46325 | R16: 45759 | S16: 46231 | T16: =Q16+(S16-P16) -> 46416 | U16: Energized on 17-Mar-26 | Other Circuit depends on Outage | Expected - 31-Oct-26
A17: =A16+1 -> 14 | B17: PE-272 | C17: AL-MUNSIYAH 132/13.8KV SUB # 8273 | D17: 45120 | E17: 1 | F17: 0.9613 | G17: SEC | H17: Central | I17: Riyadh | K17: Under Approval | L17: 45609 | M17: 45609 | N17: 46272 | O17: 45670 | P17: 45670 | Q17: =N17+(P17-M17) -> 46333 | R17: 45760 | S17: 45760 | T17: =Q17+(S17-P17) -> 46423 | U17: One Circuit Energized. Other Circuit depends on Outage | Expected - 31-Oct-26
A18: =A17+1 -> 15 | B18: PE-273 | C18: ALMANFOHA 132/13.8KV SUB # 8138 | D18: 45119 | E18: 1 | F18: 0.986 | G18: SEC | H18: Central | I18: Riyadh | K18: Approved | L18: 45608 | M18: 45991 | N18: 45991 | O18: 45669 | P18: 46052 | Q18: 46325 | R18: 45759 | S18: 46142 | T18: =Q18+(S18-P18) -> 46415 | U18: One Circuit Energized on 21-Dec-25
A19: =A18+1 -> 16 | B19: PE-274 | C19: NASIRIYAH 132/13.8KV SUB # 8154 | D19: 45119 | E19: 1 | F19: 0.927 | G19: SEC | H19: Central | I19: Riyadh | K19: Approved | L19: 45608 | M19: 46034 | N19: 46022 | O19: 45669 | P19: 46093 | Q19: 46203 | R19: 45759 | S19: 46185 | T19: =Q19+(S19-P19) -> 46295 | U19: One Energized on 11-Feb-26. TCC received with dated 31-Dec-2025
A20: =A19+1 -> 17 | B20: PE-275 | C20: 380kV Diriyah Gate-2 BSP # 9080 | D20: 45246 | E20: 0.5084 | F20: 0.4512 | G20: SEC | H20: Central | I20: Riyadh | K20: Under Approval | L20: 45977 | M20: 46490 | N20: 46547 | O20: 46038 | P20: 46550 | Q20: =N20+(P20-M20) -> 46607 | R20: 46128 | S20: 46641 | T20: =Q20+(S20-P20) -> 46698 | U20: Progress based on Internal Baseline. 1-Delay in approval of water proofing VO & removal of loose material, which affects the construction works. 2- Negative Cash flow. 3-Claim Approval 201 Mn for prolongation & inflation costs. 4- Delivery for disconnector switch expected to be delayed.
A21: =A20+1 -> 18 | B21: PE-276 | C21: SHARAFIYAH 380 KV SS | D21: 45139 | E21: 1 | F21: 0.9378 | G21: SEC | H21: Central | I21: Riyadh | K21: Under Approval | L21: 45689 | M21: 45689 | N21: 46183 | O21: 45748 | P21: 45748 | Q21: =N21+(P21-M21) -> 46242 | R21: 45839 | S21: 45839 | T21: =Q21+(S21-P21) -> 46333 | U21: Partially Energized. 1.Taihan - Oil Joints 2.Design Approval - 6 Remote end ( 132 kV) 3.Gantry Foundation for Existing Substation 4.Unclear Shutdown schedule for Power and Communication link with all remote ends 5. Delay in Micro Trenching of FOC 25km
A22: =A21+1 -> 19 | B22: PE-279 | C22: AL-NAZEEM 132/13.8KV SS # 8271 | D22: 45131 | E22: 1 | F22: 0.9085 | G22: SEC | H22: Central | I22: Riyadh | K22: Approved | L22: 45619 | M22: 45831 | N22: 46387 | O22: 45680 | P22: 45892 | Q22: =N22+(P22-M22) -> 46448 | R22: 45770 | S22: 45984 | T22: =Q22+(S22-P22) -> 46540 | U22: Commissioing on Hold due to non-readiness of UG Contractor
A23: =A22+1 -> 20 | B23: PE-299 | C23: Reinf of 132KV Network of Baqaa | D23: 45238 | E23: 0.9992 | F23: 0.9358 | G23: SEC | H23: Central | I23: Riyadh | J23: 45931 | K23: Approved | L23: 45784 | M23: 45981 | N23: 46326 | O23: 45876 | P23: 46073 | Q23: =N23+(P23-M23) -> 46418 | R23: 45937 | S23: 46132 | T23: =Q23+(S23-P23) -> 46477 | U23: 1.OHTL S/C & D/C crossing - Delay in HOT permits 2.Cutting point outage at TEE OFF location. 3.ERS System & TEE- OFF Tower Installation 4.Design Approval of Flood Protection
A24: =A23+1 -> 21 | B24: PE-300 | C24: 300 MVAR STATCOM | D24: 45357 | E24: 0.7928 | F24: 0.6916 | G24: SEC | H24: Central | I24: Riyadh | J24: 46127 | K24: Under Approval | L24: 46087 | M24: 46271 | N24: 46315 | O24: 46148 | P24: 46332 | Q24: =N24+(P24-M24) -> 46376 | R24: 46240 | S24: 46059 | T24: =Q24+(S24-P24) -> 46103 | U24: 1.Delay in delivery of AES scope material. (delay in these materials ,impact the project completion ) 2.Delay in 380 kv insulator (Lapp) 3.New fire pump-Delivery (change order), 4.Delay in delivery of MV grounding transformer
A25: =A24+1 -> 22 | B25: PE-306 | C25: NEW AL-ARED 380/132KV BSP | D25: 45218 | E25: 1 | F25: 0.9468 | G25: SEC | H25: Central | I25: Riyadh | J25: 45963 | K25: Under Approval | L25: 45766 | M25: 45888 | N25: 46203 | O25: 45829 | P25: 45949 | Q25: =N25+(P25-M25) -> 46264 | R25: 45919 | S25: 46041 | T25: =Q25+(S25-P25) -> 46356 | U25: 1.Slow Punch list - Transformers ,GIS, AES 2.Delay in SEC UG Cable Vendor - New Line( Circuits 3 )
A26: =A25+1 -> 23 | B26: PE-309 | C26: Reliablity Enh.for SS of 9011 in Sudair | D26: 46015 | E26: 0.4504 | F26: 0.2189 | G26: SEC | H26: Central | I26: Riyadh | K26: N/A | L26: 46349 | M26: 46349 | N26: 46498 | O26: 46410 | P26: 46410 | Q26: =N26+(P26-M26) -> 46559 | R26: 46500 | S26: 46500 | T26: =Q26+(S26-P26) -> 46649 | U26: Current issues 1.Delay in Plan & Profile - OHTL 2.Delay in Plan & Profile - UG Cable ( T- off Tower Location) 3.Delay in SE supply GIS Bays 4.Delay in Material :- Tower, Hardware, Insulator 5. Delay in providing existing Design : Remote End, U/G 8500 to 8521, Basement & Sleeves Details, Telecom Room, Control Room Layouts 6.Delay in Mobilization of Project Team OHTL Site Engr & Project Engr, QA & QC Civil & Electrical 7. Unclear Shutdown for Project
A27: =A26+1 -> 24 | B27: PE-310 | C27: Al Shifa Housing 132/13.8KV SS | D27: 45313 | E27: 0.946 | F27: 0.8692 | G27: SEC | H27: Central | I27: Riyadh | J27: 46049 | K27: Approved | L27: 45983 | M27: 46194 | N27: 46251 | O27: 46043 | P27: 46255 | Q27: =N27+(P27-M27) -> 46312 | R27: 46133 | S27: 46347 | T27: =Q27+(S27-P27) -> 46404 | U27: 1.Incomplete HV underground cable works under another contractor’s scope are impacting the substation energization activities. 2.STATCOM PQS approval remains pending with SEC/vendor, affecting material delivery and subsequent installation. 3.Delay in remote end (8131) works due to pending C1 work permit
A28: =A27+1 -> 25 | B28: PE-326 | C28: Shaqra Wind 380/132kV SS | D28: 45589 | E28: 0.9675 | F28: 0.6877 | G28: SEC | H28: Central | I28: Riyadh | K28: Under Approval | L28: 46165 | M28: 46165 | N28: 46387 | O28: 46226 | P28: 46226 | Q28: =N28+(P28-M28) -> 46448 | R28: 46318 | S28: 46318 | T28: =Q28+(S28-P28) -> 46540 | U28: 1-Delay in the delivery of 132kV and 380kV GIB and Hybrid GIS (SEC Direct purchase) beyond the scheduled dates, where the original plan was December 2025; however, only the 132kV GIB was delivered in end of May 2026, while the 380kV GIB and Hybrid GIS are still pending. 2-Delay in the supply of AC and DC panels from AES up to date. 3- Delay in obtaining ITP approvals for DSM and TFR systems AES prequalification to perform the FAT in AES factory. 4-Change order confirmation for the additional scope , which holding following activities (Civil work for Search facilities - Guard house - security building and along with all septic tank and water connections , HCIS stage 3 finalization and approval , Procurement of all electrical , mechanical , security material related to this pending . 5-Delay in the approval of firefighting system designs due to changing multiple changes in the review process from SEC and adding new comments with each revision. 6- After approval of lightening panels design (MS Hawaa ) SEC insist to change the manufactural to new alternate as (MS hawaa )is currently suspended in the system 7- Confirmation of EOT which submitted 9-Apr-26.
A29: =A28+1 -> 26 | B29: PE-335 | C29: Battery Energy (BESS) - Qaisumah | D29: 45642 | E29: 1 | F29: 0.9563 | G29: SEC | H29: Central | I29: Riyadh | K29: N/A | L29: 46158 | M29: 46158 | N29: 46153 | O29: 46219 | P29: 46219 | Q29: =N29+(P29-M29) -> 46214 | R29: 46311 | S29: 46311 | T29: =Q29+(S29-P29) -> 46306 | U29: Energized.
A30: =A29+1 -> 27 | B30: PE-336 | C30: Battery Energy (BESS) - Dawadmi | D30: 45642 | E30: 1 | F30: 0.9766 | G30: SEC | H30: Central | I30: Riyadh | K30: N/A | L30: 46158 | M30: 46158 | N30: 46152 | O30: 46219 | P30: 46219 | Q30: =N30+(P30-M30) -> 46213 | R30: 46311 | S30: 46311 | T30: =Q30+(S30-P30) -> 46305 | U30: Energized.
A31: =A30+1 -> 28 | B31: PE-337 | C31: Battery Energy (BESS) - Airport | D31: 45642 | E31: 1 | F31: 0.9883 | G31: SEC | H31: Central | I31: Riyadh | K31: N/A | L31: 46158 | M31: 46158 | N31: 46148 | O31: 46219 | P31: 46219 | Q31: =N31+(P31-M31) -> 46209 | R31: 46311 | S31: 46311 | T31: =Q31+(S31-P31) -> 46301 | U31: Energized.
